    <html>
    <head>
<style>
.failure {
background-color: orangered;
}
.success {
background-color: springgreen;
}
</style>
    </head>
    <body>
	<h1>Testing logs for Python</h1>
	<p>Running at Tue 20 Oct 2020 04:08:36 AM EDT</p>
  <div id="summary0" class="failure">
    <h2><a href="python_logs.html#pythonlog0">Assignment 0</a> </h2>
    <p>
      <ul>
        <li> Run : <a href="python_logs.html#pythonlog0-runanswer">error</a></li>
      </ul>
    </p>
  </div>
  <div id="summary1" class="failure">
    <h2><a href="python_logs.html#pythonlog1">Assignment 1</a> </h2>
    <p>
      <ul>
        <li> Run : <a href="python_logs.html#pythonlog1-runanswer">error</a></li>
      </ul>
    </p>
  </div>
  <div id="summary2" class="failure">
    <h2><a href="python_logs.html#pythonlog2">Assignment 2</a> </h2>
    <p>
      <ul>
        <li> Run : <a href="python_logs.html#pythonlog2-runanswer">error</a></li>
      </ul>
    </p>
  </div>
  <div id="summary3" class="failure">
    <h2><a href="python_logs.html#pythonlog3">Assignment 3</a> </h2>
    <p>
      <ul>
        <li> Run : <a href="python_logs.html#pythonlog3-runanswer">error</a></li>
      </ul>
    </p>
  </div>
  <div id="summary4" class="failure">
    <h2><a href="python_logs.html#pythonlog4">Assignment 4</a> </h2>
    <p>
      <ul>
        <li> Run : <a href="python_logs.html#pythonlog4-runanswer">error</a></li>
      </ul>
    </p>
  </div>
  <div id="summary5" class="failure">
    <h2><a href="python_logs.html#pythonlog5">Assignment 5</a> </h2>
    <p>
      <ul>
        <li> Run : <a href="python_logs.html#pythonlog5-runanswer">error</a></li>
      </ul>
    </p>
  </div>
  <div id="summary6" class="failure">
    <h2><a href="python_logs.html#pythonlog6">Assignment 6</a> </h2>
    <p>
      <ul>
        <li> Run : <a href="python_logs.html#pythonlog6-runanswer">error</a></li>
      </ul>
    </p>
  </div>
  <div id="summary7" class="failure">
    <h2><a href="python_logs.html#pythonlog7">Assignment 7</a> </h2>
    <p>
      <ul>
        <li> Run : <a href="python_logs.html#pythonlog7-runanswer">error</a></li>
      </ul>
    </p>
  </div>
  <div id="summary8" class="failure">
    <h2><a href="python_logs.html#pythonlog8">Assignment 8</a> </h2>
    <p>
      <ul>
        <li> Run : <a href="python_logs.html#pythonlog8-runanswer">error</a></li>
      </ul>
    </p>
  </div>
  <div id="summary9" class="failure">
    <h2><a href="python_logs.html#pythonlog9">Assignment 9</a> </h2>
    <p>
      <ul>
        <li> Run : <a href="python_logs.html#pythonlog9-runanswer">error</a></li>
      </ul>
    </p>
  </div>
  <div id="summary10" class="failure">
    <h2><a href="python_logs.html#pythonlog10">Assignment 10</a> </h2>
    <p>
      <ul>
        <li> Run : <a href="python_logs.html#pythonlog10-runanswer">error</a></li>
      </ul>
    </p>
  </div>
  <div id="summary11" class="failure">
    <h2><a href="python_logs.html#pythonlog11">Assignment 11</a> </h2>
    <p>
      <ul>
        <li> Run : <a href="python_logs.html#pythonlog11-runanswer">error</a></li>
      </ul>
    </p>
  </div>
  <div id="summary12" class="failure">
    <h2><a href="python_logs.html#pythonlog12">Assignment 12</a> </h2>
    <p>
      <ul>
        <li> Run : <a href="python_logs.html#pythonlog12-runanswer">error</a></li>
      </ul>
    </p>
  </div>
  <div id="summary13" class="failure">
    <h2><a href="python_logs.html#pythonlog13">Assignment 13</a> </h2>
    <p>
      <ul>
        <li> Run : <a href="python_logs.html#pythonlog13-runanswer">error</a></li>
      </ul>
    </p>
  </div>
  <div id="summary14" class="failure">
    <h2><a href="python_logs.html#pythonlog14">Assignment 14</a> </h2>
    <p>
      <ul>
        <li> Run : <a href="python_logs.html#pythonlog14-runanswer">error</a></li>
      </ul>
    </p>
  </div>
  <div id="summary15" class="failure">
    <h2><a href="python_logs.html#pythonlog15">Assignment 15</a> </h2>
    <p>
      <ul>
        <li> Run : <a href="python_logs.html#pythonlog15-runanswer">error</a></li>
      </ul>
    </p>
  </div>
  <div id="summary16" class="failure">
    <h2><a href="python_logs.html#pythonlog16">Assignment 16</a> </h2>
    <p>
      <ul>
        <li> Run : <a href="python_logs.html#pythonlog16-runanswer">error</a></li>
      </ul>
    </p>
  </div>
  <div id="summary17" class="failure">
    <h2><a href="python_logs.html#pythonlog17">Assignment 17</a> </h2>
    <p>
      <ul>
        <li> Run : <a href="python_logs.html#pythonlog17-runanswer">error</a></li>
      </ul>
    </p>
  </div>
  <div id="summary18" class="failure">
    <h2><a href="python_logs.html#pythonlog18">Assignment 18</a> </h2>
    <p>
      <ul>
        <li> Run : <a href="python_logs.html#pythonlog18-runanswer">error</a></li>
      </ul>
    </p>
  </div>
  <div id="summary19" class="failure">
    <h2><a href="python_logs.html#pythonlog19">Assignment 19</a> </h2>
    <p>
      <ul>
        <li> Run : <a href="python_logs.html#pythonlog19-runanswer">error</a></li>
      </ul>
    </p>
  </div>
  <div id="summary20" class="failure">
    <h2><a href="python_logs.html#pythonlog20">Assignment 20</a> </h2>
    <p>
      <ul>
        <li> Run : <a href="python_logs.html#pythonlog20-runanswer">error</a></li>
      </ul>
    </p>
  </div>
  <div id="summary21" class="failure">
    <h2><a href="python_logs.html#pythonlog21">Assignment 21</a> </h2>
    <p>
      <ul>
        <li> Run : <a href="python_logs.html#pythonlog21-runanswer">error</a></li>
      </ul>
    </p>
  </div>
  <div id="summary22" class="failure">
    <h2><a href="python_logs.html#pythonlog22">Assignment 22</a> </h2>
    <p>
      <ul>
        <li> Run : <a href="python_logs.html#pythonlog22-runanswer">error</a></li>
      </ul>
    </p>
  </div>
  <div id="summary23" class="failure">
    <h2><a href="python_logs.html#pythonlog23">Assignment 23</a> </h2>
    <p>
      <ul>
        <li> Run : <a href="python_logs.html#pythonlog23-runanswer">error</a></li>
      </ul>
    </p>
  </div>
  <div id="summary24" class="failure">
    <h2><a href="python_logs.html#pythonlog24">Assignment 24</a> </h2>
    <p>
      <ul>
        <li> Run : <a href="python_logs.html#pythonlog24-runanswer">error</a></li>
      </ul>
    </p>
  </div>
  <div id="summary25" class="failure">
    <h2><a href="python_logs.html#pythonlog25">Assignment 25</a> </h2>
    <p>
      <ul>
        <li> Run : <a href="python_logs.html#pythonlog25-runanswer">error</a></li>
      </ul>
    </p>
  </div>
  <div id="summary26" class="failure">
    <h2><a href="python_logs.html#pythonlog26">Assignment 26</a> </h2>
    <p>
      <ul>
        <li> Run : <a href="python_logs.html#pythonlog26-runanswer">error</a></li>
      </ul>
    </p>
  </div>
  <div id="summary27" class="failure">
    <h2><a href="python_logs.html#pythonlog27">Assignment 27</a> </h2>
    <p>
      <ul>
        <li> Run : <a href="python_logs.html#pythonlog27-runanswer">error</a></li>
      </ul>
    </p>
  </div>
  <div id="summary28" class="failure">
    <h2><a href="python_logs.html#pythonlog28">Assignment 28</a> </h2>
    <p>
      <ul>
        <li> Run : <a href="python_logs.html#pythonlog28-runanswer">error</a></li>
      </ul>
    </p>
  </div>
  <div id="summary29" class="failure">
    <h2><a href="python_logs.html#pythonlog29">Assignment 29</a> </h2>
    <p>
      <ul>
        <li> Run : <a href="python_logs.html#pythonlog29-runanswer">error</a></li>
      </ul>
    </p>
  </div>
  <div id="summary30" class="failure">
    <h2><a href="python_logs.html#pythonlog30">Assignment 30</a> </h2>
    <p>
      <ul>
        <li> Run : <a href="python_logs.html#pythonlog30-runanswer">error</a></li>
      </ul>
    </p>
  </div>
  <div id="summary31" class="failure">
    <h2><a href="python_logs.html#pythonlog31">Assignment 31</a> </h2>
    <p>
      <ul>
        <li> Run : <a href="python_logs.html#pythonlog31-runanswer">error</a></li>
      </ul>
    </p>
  </div>
  <div id="summary32" class="failure">
    <h2><a href="python_logs.html#pythonlog32">Assignment 32</a> </h2>
    <p>
      <ul>
        <li> Run : <a href="python_logs.html#pythonlog32-runanswer">error</a></li>
      </ul>
    </p>
  </div>
  <div id="summary33" class="failure">
    <h2><a href="python_logs.html#pythonlog33">Assignment 33</a> </h2>
    <p>
      <ul>
        <li> Run : <a href="python_logs.html#pythonlog33-runanswer">error</a></li>
      </ul>
    </p>
  </div>
  <div id="summary34" class="failure">
    <h2><a href="python_logs.html#pythonlog34">Assignment 34</a> </h2>
    <p>
      <ul>
        <li> Run : <a href="python_logs.html#pythonlog34-runanswer">error</a></li>
      </ul>
    </p>
  </div>
  <div id="summary35" class="failure">
    <h2><a href="python_logs.html#pythonlog35">Assignment 35</a> </h2>
    <p>
      <ul>
        <li> Run : <a href="python_logs.html#pythonlog35-runanswer">error</a></li>
      </ul>
    </p>
  </div>
  <div id="summary36" class="failure">
    <h2><a href="python_logs.html#pythonlog36">Assignment 36</a> </h2>
    <p>
      <ul>
        <li> Run : <a href="python_logs.html#pythonlog36-runanswer">error</a></li>
      </ul>
    </p>
  </div>
  <div id="summary37" class="failure">
    <h2><a href="python_logs.html#pythonlog37">Assignment 37</a> </h2>
    <p>
      <ul>
        <li> Run : <a href="python_logs.html#pythonlog37-runanswer">error</a></li>
      </ul>
    </p>
  </div>
  <div id="summary38" class="failure">
    <h2><a href="python_logs.html#pythonlog38">Assignment 38</a> </h2>
    <p>
      <ul>
        <li> Run : <a href="python_logs.html#pythonlog38-runanswer">error</a></li>
      </ul>
    </p>
  </div>
  <div id="summary39" class="failure">
    <h2><a href="python_logs.html#pythonlog39">Assignment 39</a> </h2>
    <p>
      <ul>
        <li> Run : <a href="python_logs.html#pythonlog39-runanswer">error</a></li>
      </ul>
    </p>
  </div>
  <div id="summary40" class="failure">
    <h2><a href="python_logs.html#pythonlog40">Assignment 40</a> </h2>
    <p>
      <ul>
        <li> Run : <a href="python_logs.html#pythonlog40-runanswer">error</a></li>
      </ul>
    </p>
  </div>
  <div id="summary41" class="failure">
    <h2><a href="python_logs.html#pythonlog41">Assignment 41</a> </h2>
    <p>
      <ul>
        <li> Run : <a href="python_logs.html#pythonlog41-runanswer">error</a></li>
      </ul>
    </p>
  </div>
  <div id="summary42" class="failure">
    <h2><a href="python_logs.html#pythonlog42">Assignment 42</a> </h2>
    <p>
      <ul>
        <li> Run : <a href="python_logs.html#pythonlog42-runanswer">error</a></li>
      </ul>
    </p>
  </div>
  <div id="summary43" class="success">
    <h2><a href="python_logs.html#pythonlog43">Assignment 43</a> </h2>
    <p>
      <ul>
        <li> Run : <a href="python_logs.html#pythonlog43-runanswer">success</a></li>
      </ul>
    </p>
  </div>
  <div id="summary44" class="failure">
    <h2><a href="python_logs.html#pythonlog44">Assignment 44</a> </h2>
    <p>
      <ul>
        <li> Run : <a href="python_logs.html#pythonlog44-runanswer">error</a></li>
      </ul>
    </p>
  </div>
  <div id="summary45" class="success">
    <h2><a href="python_logs.html#pythonlog45">Assignment 45</a> </h2>
    <p>
      <ul>
        <li> Run : <a href="python_logs.html#pythonlog45-runanswer">success</a></li>
      </ul>
    </p>
  </div>
  <div id="summary46" class="failure">
    <h2><a href="python_logs.html#pythonlog46">Assignment 46</a> </h2>
    <p>
      <ul>
        <li> Run : <a href="python_logs.html#pythonlog46-runanswer">error</a></li>
      </ul>
    </p>
  </div>
  <div id="summary47" class="failure">
    <h2><a href="python_logs.html#pythonlog47">Assignment 47</a> </h2>
    <p>
      <ul>
        <li> Run : <a href="python_logs.html#pythonlog47-runanswer">error</a></li>
      </ul>
    </p>
  </div>
  <div id="summary48" class="failure">
    <h2><a href="python_logs.html#pythonlog48">Assignment 48</a> </h2>
    <p>
      <ul>
        <li> Run : <a href="python_logs.html#pythonlog48-runanswer">error</a></li>
      </ul>
    </p>
  </div>
  <div id="summary49" class="failure">
    <h2><a href="python_logs.html#pythonlog49">Assignment 49</a> </h2>
    <p>
      <ul>
        <li> Run : <a href="python_logs.html#pythonlog49-runanswer">error</a></li>
      </ul>
    </p>
  </div>
  <div id="summary50" class="failure">
    <h2><a href="python_logs.html#pythonlog50">Assignment 50</a> </h2>
    <p>
      <ul>
        <li> Run : <a href="python_logs.html#pythonlog50-runanswer">error</a></li>
      </ul>
    </p>
  </div>
  <div id="summary51" class="failure">
    <h2><a href="python_logs.html#pythonlog51">Assignment 51</a> </h2>
    <p>
      <ul>
        <li> Run : <a href="python_logs.html#pythonlog51-runanswer">error</a></li>
      </ul>
    </p>
  </div>
  <div id="summary52" class="failure">
    <h2><a href="python_logs.html#pythonlog52">Assignment 52</a> </h2>
    <p>
      <ul>
        <li> Run : <a href="python_logs.html#pythonlog52-runanswer">error</a></li>
      </ul>
    </p>
  </div>
  <div id="summary53" class="failure">
    <h2><a href="python_logs.html#pythonlog53">Assignment 53</a> </h2>
    <p>
      <ul>
        <li> Run : <a href="python_logs.html#pythonlog53-runanswer">error</a></li>
      </ul>
    </p>
  </div>
  <div id="summary54" class="failure">
    <h2><a href="python_logs.html#pythonlog54">Assignment 54</a> </h2>
    <p>
      <ul>
        <li> Run : <a href="python_logs.html#pythonlog54-runanswer">error</a></li>
      </ul>
    </p>
  </div>
  <div id="summary55" class="failure">
    <h2><a href="python_logs.html#pythonlog55">Assignment 55</a> </h2>
    <p>
      <ul>
        <li> Run : <a href="python_logs.html#pythonlog55-runanswer">error</a></li>
      </ul>
    </p>
  </div>
    <div id="pythonlog0" class="logdetails">
      <h2>Assignment 0 full log</h2>
    
<div class="failure">
<h3><span id="pythonlog0-runanswer">Run for Assignment 0</span></h3>
<pre><code>Guessing setup.py is the python file where main is

Traceback (most recent call last):
  File &quot;/usr/lib/python3/dist-packages/urllib3/connection.py&quot;, line 159, in _new_conn
    (self._dns_host, self.port), self.timeout, **extra_kw)
  File &quot;/usr/lib/python3/dist-packages/urllib3/util/connection.py&quot;, line 57, in create_connection
    for res in socket.getaddrinfo(host, port, family, socket.SOCK_STREAM):
  File &quot;/usr/lib/python3.7/socket.py&quot;, line 748, in getaddrinfo
    for res in _socket.getaddrinfo(host, port, family, type, proto, flags):
socket.gaierror: [Errno -2] Name or service not known

During handling of the above exception, another exception occurred:

Traceback (most recent call last):
  File &quot;/usr/lib/python3/dist-packages/urllib3/connectionpool.py&quot;, line 600, in urlopen
    chunked=chunked)
  File &quot;/usr/lib/python3/dist-packages/urllib3/connectionpool.py&quot;, line 354, in _make_request
    conn.request(method, url, **httplib_request_kw)
  File &quot;/usr/lib/python3.7/http/client.py&quot;, line 1244, in request
    self._send_request(method, url, body, headers, encode_chunked)
  File &quot;/usr/lib/python3.7/http/client.py&quot;, line 1290, in _send_request
    self.endheaders(body, encode_chunked=encode_chunked)
  File &quot;/usr/lib/python3.7/http/client.py&quot;, line 1239, in endheaders
    self._send_output(message_body, encode_chunked=encode_chunked)
  File &quot;/usr/lib/python3.7/http/client.py&quot;, line 1026, in _send_output
    self.send(msg)
  File &quot;/usr/lib/python3.7/http/client.py&quot;, line 966, in send
    self.connect()
  File &quot;/usr/lib/python3/dist-packages/urllib3/connection.py&quot;, line 181, in connect
    conn = self._new_conn()
  File &quot;/usr/lib/python3/dist-packages/urllib3/connection.py&quot;, line 168, in _new_conn
    self, &quot;Failed to establish a new connection: %s&quot; % e)
urllib3.exceptions.NewConnectionError: &lt;urllib3.connection.HTTPConnection object at 0x7fb357462cc0&gt;: Failed to establish a new connection: [Errno -2] Name or service not known

During handling of the above exception, another exception occurred:

Traceback (most recent call last):
  File &quot;/usr/lib/python3/dist-packages/requests/adapters.py&quot;, line 449, in send
    timeout=timeout
  File &quot;/usr/lib/python3/dist-packages/urllib3/connectionpool.py&quot;, line 638, in urlopen
    _stacktrace=sys.exc_info()[2])
  File &quot;/usr/lib/python3/dist-packages/urllib3/util/retry.py&quot;, line 398, in increment
    raise MaxRetryError(_pool, url, error or ResponseError(cause))
urllib3.exceptions.MaxRetryError: HTTPConnectionPool(host='bridges-cs.herokuapp.com', port=80): Max retries exceeded with url: /assignments/200.00?apikey=1321549621122&amp;username=bridges_testing (Caused by NewConnectionError('&lt;urllib3.connection.HTTPConnection object at 0x7fb357462cc0&gt;: Failed to establish a new connection: [Errno -2] Name or service not known'))

During handling of the above exception, another exception occurred:

Traceback (most recent call last):
  File &quot;setup.py&quot;, line 32, in &lt;module&gt;
    main()
  File &quot;setup.py&quot;, line 29, in main
    bridges.visualize()
  File &quot;/home/bridges-testing/.local/lib/python3.7/site-packages/bridges-3.1.1-py3.7.egg/bridges/bridges.py&quot;, line 174, in visualize
  File &quot;/home/bridges-testing/.local/lib/python3.7/site-packages/bridges-3.1.1-py3.7.egg/bridges/connector.py&quot;, line 64, in post
  File &quot;/usr/lib/python3/dist-packages/requests/api.py&quot;, line 116, in post
    return request('post', url, data=data, json=json, **kwargs)
  File &quot;/usr/lib/python3/dist-packages/requests/api.py&quot;, line 60, in request
    return session.request(method=method, url=url, **kwargs)
  File &quot;/usr/lib/python3/dist-packages/requests/sessions.py&quot;, line 533, in request
    resp = self.send(prep, **send_kwargs)
  File &quot;/usr/lib/python3/dist-packages/requests/sessions.py&quot;, line 646, in send
    r = adapter.send(request, **kwargs)
  File &quot;/usr/lib/python3/dist-packages/requests/adapters.py&quot;, line 516, in send
    raise ConnectionError(e, request=request)
requests.exceptions.ConnectionError: HTTPConnectionPool(host='bridges-cs.herokuapp.com', port=80): Max retries exceeded with url: /assignments/200.00?apikey=1321549621122&amp;username=bridges_testing (Caused by NewConnectionError('&lt;urllib3.connection.HTTPConnection object at 0x7fb357462cc0&gt;: Failed to establish a new connection: [Errno -2] Name or service not known'))
could not run python_answer for assignment in ../assignmentdb/0-Setup/python_answer
</code></pre>
</div>
    
    </div>
    <div id="pythonlog1" class="logdetails">
      <h2>Assignment 1 full log</h2>
    
<div class="failure">
<h3><span id="pythonlog1-runanswer">Run for Assignment 1</span></h3>
<pre><code>Guessing ListIMDB.py is the python file where main is

Traceback (most recent call last):
  File &quot;/usr/lib/python3/dist-packages/urllib3/connection.py&quot;, line 159, in _new_conn
    (self._dns_host, self.port), self.timeout, **extra_kw)
  File &quot;/usr/lib/python3/dist-packages/urllib3/util/connection.py&quot;, line 57, in create_connection
    for res in socket.getaddrinfo(host, port, family, socket.SOCK_STREAM):
  File &quot;/usr/lib/python3.7/socket.py&quot;, line 748, in getaddrinfo
    for res in _socket.getaddrinfo(host, port, family, type, proto, flags):
socket.gaierror: [Errno -2] Name or service not known

During handling of the above exception, another exception occurred:

Traceback (most recent call last):
  File &quot;/usr/lib/python3/dist-packages/urllib3/connectionpool.py&quot;, line 600, in urlopen
    chunked=chunked)
  File &quot;/usr/lib/python3/dist-packages/urllib3/connectionpool.py&quot;, line 354, in _make_request
    conn.request(method, url, **httplib_request_kw)
  File &quot;/usr/lib/python3.7/http/client.py&quot;, line 1244, in request
    self._send_request(method, url, body, headers, encode_chunked)
  File &quot;/usr/lib/python3.7/http/client.py&quot;, line 1290, in _send_request
    self.endheaders(body, encode_chunked=encode_chunked)
  File &quot;/usr/lib/python3.7/http/client.py&quot;, line 1239, in endheaders
    self._send_output(message_body, encode_chunked=encode_chunked)
  File &quot;/usr/lib/python3.7/http/client.py&quot;, line 1026, in _send_output
    self.send(msg)
  File &quot;/usr/lib/python3.7/http/client.py&quot;, line 966, in send
    self.connect()
  File &quot;/usr/lib/python3/dist-packages/urllib3/connection.py&quot;, line 181, in connect
    conn = self._new_conn()
  File &quot;/usr/lib/python3/dist-packages/urllib3/connection.py&quot;, line 168, in _new_conn
    self, &quot;Failed to establish a new connection: %s&quot; % e)
urllib3.exceptions.NewConnectionError: &lt;urllib3.connection.HTTPConnection object at 0x7f07878028d0&gt;: Failed to establish a new connection: [Errno -2] Name or service not known

During handling of the above exception, another exception occurred:

Traceback (most recent call last):
  File &quot;/usr/lib/python3/dist-packages/requests/adapters.py&quot;, line 449, in send
    timeout=timeout
  File &quot;/usr/lib/python3/dist-packages/urllib3/connectionpool.py&quot;, line 638, in urlopen
    _stacktrace=sys.exc_info()[2])
  File &quot;/usr/lib/python3/dist-packages/urllib3/util/retry.py&quot;, line 398, in increment
    raise MaxRetryError(_pool, url, error or ResponseError(cause))
urllib3.exceptions.MaxRetryError: HTTPConnectionPool(host='bridgesdata.herokuapp.com', port=80): Max retries exceeded with url: /api/imdb?limit=0&amp;%7B'Accept:%20application/json'%7D (Caused by NewConnectionError('&lt;urllib3.connection.HTTPConnection object at 0x7f07878028d0&gt;: Failed to establish a new connection: [Errno -2] Name or service not known'))

During handling of the above exception, another exception occurred:

Traceback (most recent call last):
  File &quot;ListIMDB.py&quot;, line 26, in &lt;module&gt;
    main()
  File &quot;ListIMDB.py&quot;, line 10, in main
    data = get_actor_movie_imdb_data()
  File &quot;/home/bridges-testing/.local/lib/python3.7/site-packages/bridges-3.1.1-py3.7.egg/bridges/data_src_dependent/data_source.py&quot;, line 84, in get_actor_movie_imdb_data
  File &quot;/usr/lib/python3/dist-packages/requests/api.py&quot;, line 75, in get
    return request('get', url, params=params, **kwargs)
  File &quot;/usr/lib/python3/dist-packages/requests/api.py&quot;, line 60, in request
    return session.request(method=method, url=url, **kwargs)
  File &quot;/usr/lib/python3/dist-packages/requests/sessions.py&quot;, line 533, in request
    resp = self.send(prep, **send_kwargs)
  File &quot;/usr/lib/python3/dist-packages/requests/sessions.py&quot;, line 646, in send
    r = adapter.send(request, **kwargs)
  File &quot;/usr/lib/python3/dist-packages/requests/adapters.py&quot;, line 516, in send
    raise ConnectionError(e, request=request)
requests.exceptions.ConnectionError: HTTPConnectionPool(host='bridgesdata.herokuapp.com', port=80): Max retries exceeded with url: /api/imdb?limit=0&amp;%7B'Accept:%20application/json'%7D (Caused by NewConnectionError('&lt;urllib3.connection.HTTPConnection object at 0x7f07878028d0&gt;: Failed to establish a new connection: [Errno -2] Name or service not known'))
could not run python_answer for assignment in ../assignmentdb/1-ListIMDB/python_answer
</code></pre>
</div>
    
    </div>
    <div id="pythonlog2" class="logdetails">
      <h2>Assignment 2 full log</h2>
    
<div class="failure">
<h3><span id="pythonlog2-runanswer">Run for Assignment 2</span></h3>
<pre><code>Guessing ListEQ.py is the python file where main is

Traceback (most recent call last):
  File &quot;/usr/lib/python3/dist-packages/urllib3/connection.py&quot;, line 159, in _new_conn
    (self._dns_host, self.port), self.timeout, **extra_kw)
  File &quot;/usr/lib/python3/dist-packages/urllib3/util/connection.py&quot;, line 57, in create_connection
    for res in socket.getaddrinfo(host, port, family, socket.SOCK_STREAM):
  File &quot;/usr/lib/python3.7/socket.py&quot;, line 748, in getaddrinfo
    for res in _socket.getaddrinfo(host, port, family, type, proto, flags):
socket.gaierror: [Errno -2] Name or service not known

During handling of the above exception, another exception occurred:

Traceback (most recent call last):
  File &quot;/usr/lib/python3/dist-packages/urllib3/connectionpool.py&quot;, line 600, in urlopen
    chunked=chunked)
  File &quot;/usr/lib/python3/dist-packages/urllib3/connectionpool.py&quot;, line 354, in _make_request
    conn.request(method, url, **httplib_request_kw)
  File &quot;/usr/lib/python3.7/http/client.py&quot;, line 1244, in request
    self._send_request(method, url, body, headers, encode_chunked)
  File &quot;/usr/lib/python3.7/http/client.py&quot;, line 1290, in _send_request
    self.endheaders(body, encode_chunked=encode_chunked)
  File &quot;/usr/lib/python3.7/http/client.py&quot;, line 1239, in endheaders
    self._send_output(message_body, encode_chunked=encode_chunked)
  File &quot;/usr/lib/python3.7/http/client.py&quot;, line 1026, in _send_output
    self.send(msg)
  File &quot;/usr/lib/python3.7/http/client.py&quot;, line 966, in send
    self.connect()
  File &quot;/usr/lib/python3/dist-packages/urllib3/connection.py&quot;, line 181, in connect
    conn = self._new_conn()
  File &quot;/usr/lib/python3/dist-packages/urllib3/connection.py&quot;, line 168, in _new_conn
    self, &quot;Failed to establish a new connection: %s&quot; % e)
urllib3.exceptions.NewConnectionError: &lt;urllib3.connection.HTTPConnection object at 0x7f2592b7ea58&gt;: Failed to establish a new connection: [Errno -2] Name or service not known

During handling of the above exception, another exception occurred:

Traceback (most recent call last):
  File &quot;/usr/lib/python3/dist-packages/requests/adapters.py&quot;, line 449, in send
    timeout=timeout
  File &quot;/usr/lib/python3/dist-packages/urllib3/connectionpool.py&quot;, line 638, in urlopen
    _stacktrace=sys.exc_info()[2])
  File &quot;/usr/lib/python3/dist-packages/urllib3/util/retry.py&quot;, line 398, in increment
    raise MaxRetryError(_pool, url, error or ResponseError(cause))
urllib3.exceptions.MaxRetryError: HTTPConnectionPool(host='earthquakes-uncc.herokuapp.com', port=80): Max retries exceeded with url: /eq/latest/100?%7B'Accept:%20application/json'%7D (Caused by NewConnectionError('&lt;urllib3.connection.HTTPConnection object at 0x7f2592b7ea58&gt;: Failed to establish a new connection: [Errno -2] Name or service not known'))

During handling of the above exception, another exception occurred:

Traceback (most recent call last):
  File &quot;ListEQ.py&quot;, line 66, in &lt;module&gt;
    main()
  File &quot;ListEQ.py&quot;, line 46, in main
    data = get_earthquake_usgs_data(100)
  File &quot;/home/bridges-testing/.local/lib/python3.7/site-packages/bridges-3.1.1-py3.7.egg/bridges/data_src_dependent/data_source.py&quot;, line 154, in get_earthquake_usgs_data
  File &quot;/usr/lib/python3/dist-packages/requests/api.py&quot;, line 75, in get
    return request('get', url, params=params, **kwargs)
  File &quot;/usr/lib/python3/dist-packages/requests/api.py&quot;, line 60, in request
    return session.request(method=method, url=url, **kwargs)
  File &quot;/usr/lib/python3/dist-packages/requests/sessions.py&quot;, line 533, in request
    resp = self.send(prep, **send_kwargs)
  File &quot;/usr/lib/python3/dist-packages/requests/sessions.py&quot;, line 646, in send
    r = adapter.send(request, **kwargs)
  File &quot;/usr/lib/python3/dist-packages/requests/adapters.py&quot;, line 516, in send
    raise ConnectionError(e, request=request)
requests.exceptions.ConnectionError: HTTPConnectionPool(host='earthquakes-uncc.herokuapp.com', port=80): Max retries exceeded with url: /eq/latest/100?%7B'Accept:%20application/json'%7D (Caused by NewConnectionError('&lt;urllib3.connection.HTTPConnection object at 0x7f2592b7ea58&gt;: Failed to establish a new connection: [Errno -2] Name or service not known'))
could not run python_answer for assignment in ../assignmentdb/2-ListEQ/python_answer
</code></pre>
</div>
    
    </div>
    <div id="pythonlog3" class="logdetails">
      <h2>Assignment 3 full log</h2>
    
<div class="failure">
<h3><span id="pythonlog3-runanswer">Run for Assignment 3</span></h3>
<pre><code>Guessing GraphBaconNumber.py is the python file where main is

Traceback (most recent call last):
  File &quot;/usr/lib/python3/dist-packages/urllib3/connection.py&quot;, line 159, in _new_conn
    (self._dns_host, self.port), self.timeout, **extra_kw)
  File &quot;/usr/lib/python3/dist-packages/urllib3/util/connection.py&quot;, line 57, in create_connection
    for res in socket.getaddrinfo(host, port, family, socket.SOCK_STREAM):
  File &quot;/usr/lib/python3.7/socket.py&quot;, line 748, in getaddrinfo
    for res in _socket.getaddrinfo(host, port, family, type, proto, flags):
socket.gaierror: [Errno -2] Name or service not known

During handling of the above exception, another exception occurred:

Traceback (most recent call last):
  File &quot;/usr/lib/python3/dist-packages/urllib3/connectionpool.py&quot;, line 600, in urlopen
    chunked=chunked)
  File &quot;/usr/lib/python3/dist-packages/urllib3/connectionpool.py&quot;, line 354, in _make_request
    conn.request(method, url, **httplib_request_kw)
  File &quot;/usr/lib/python3.7/http/client.py&quot;, line 1244, in request
    self._send_request(method, url, body, headers, encode_chunked)
  File &quot;/usr/lib/python3.7/http/client.py&quot;, line 1290, in _send_request
    self.endheaders(body, encode_chunked=encode_chunked)
  File &quot;/usr/lib/python3.7/http/client.py&quot;, line 1239, in endheaders
    self._send_output(message_body, encode_chunked=encode_chunked)
  File &quot;/usr/lib/python3.7/http/client.py&quot;, line 1026, in _send_output
    self.send(msg)
  File &quot;/usr/lib/python3.7/http/client.py&quot;, line 966, in send
    self.connect()
  File &quot;/usr/lib/python3/dist-packages/urllib3/connection.py&quot;, line 181, in connect
    conn = self._new_conn()
  File &quot;/usr/lib/python3/dist-packages/urllib3/connection.py&quot;, line 168, in _new_conn
    self, &quot;Failed to establish a new connection: %s&quot; % e)
urllib3.exceptions.NewConnectionError: &lt;urllib3.connection.HTTPConnection object at 0x7fd5f7f89d68&gt;: Failed to establish a new connection: [Errno -2] Name or service not known

During handling of the above exception, another exception occurred:

Traceback (most recent call last):
  File &quot;/usr/lib/python3/dist-packages/requests/adapters.py&quot;, line 449, in send
    timeout=timeout
  File &quot;/usr/lib/python3/dist-packages/urllib3/connectionpool.py&quot;, line 638, in urlopen
    _stacktrace=sys.exc_info()[2])
  File &quot;/usr/lib/python3/dist-packages/urllib3/util/retry.py&quot;, line 398, in increment
    raise MaxRetryError(_pool, url, error or ResponseError(cause))
urllib3.exceptions.MaxRetryError: HTTPConnectionPool(host='bridgesdata.herokuapp.com', port=80): Max retries exceeded with url: /api/imdb?limit=1814&amp;%7B'Accept:%20application/json'%7D (Caused by NewConnectionError('&lt;urllib3.connection.HTTPConnection object at 0x7fd5f7f89d68&gt;: Failed to establish a new connection: [Errno -2] Name or service not known'))

During handling of the above exception, another exception occurred:

Traceback (most recent call last):
  File &quot;GraphBaconNumber.py&quot;, line 109, in &lt;module&gt;
    main()
  File &quot;GraphBaconNumber.py&quot;, line 88, in main
    build_graph(gr)
  File &quot;GraphBaconNumber.py&quot;, line 5, in build_graph
    actor_list = get_actor_movie_imdb_data(1814)
  File &quot;/home/bridges-testing/.local/lib/python3.7/site-packages/bridges-3.1.1-py3.7.egg/bridges/data_src_dependent/data_source.py&quot;, line 84, in get_actor_movie_imdb_data
  File &quot;/usr/lib/python3/dist-packages/requests/api.py&quot;, line 75, in get
    return request('get', url, params=params, **kwargs)
  File &quot;/usr/lib/python3/dist-packages/requests/api.py&quot;, line 60, in request
    return session.request(method=method, url=url, **kwargs)
  File &quot;/usr/lib/python3/dist-packages/requests/sessions.py&quot;, line 533, in request
    resp = self.send(prep, **send_kwargs)
  File &quot;/usr/lib/python3/dist-packages/requests/sessions.py&quot;, line 646, in send
    r = adapter.send(request, **kwargs)
  File &quot;/usr/lib/python3/dist-packages/requests/adapters.py&quot;, line 516, in send
    raise ConnectionError(e, request=request)
requests.exceptions.ConnectionError: HTTPConnectionPool(host='bridgesdata.herokuapp.com', port=80): Max retries exceeded with url: /api/imdb?limit=1814&amp;%7B'Accept:%20application/json'%7D (Caused by NewConnectionError('&lt;urllib3.connection.HTTPConnection object at 0x7fd5f7f89d68&gt;: Failed to establish a new connection: [Errno -2] Name or service not known'))
could not run python_answer for assignment in ../assignmentdb/3-GraphBaconNumber/python_answer
</code></pre>
</div>
    
    </div>
    <div id="pythonlog4" class="logdetails">
      <h2>Assignment 4 full log</h2>
    
<div class="failure">
<h3><span id="pythonlog4-runanswer">Run for Assignment 4</span></h3>
<pre><code>Guessing GraphEQ.py is the python file where main is

Traceback (most recent call last):
  File &quot;/usr/lib/python3/dist-packages/urllib3/connection.py&quot;, line 159, in _new_conn
    (self._dns_host, self.port), self.timeout, **extra_kw)
  File &quot;/usr/lib/python3/dist-packages/urllib3/util/connection.py&quot;, line 57, in create_connection
    for res in socket.getaddrinfo(host, port, family, socket.SOCK_STREAM):
  File &quot;/usr/lib/python3.7/socket.py&quot;, line 748, in getaddrinfo
    for res in _socket.getaddrinfo(host, port, family, type, proto, flags):
socket.gaierror: [Errno -2] Name or service not known

During handling of the above exception, another exception occurred:

Traceback (most recent call last):
  File &quot;/usr/lib/python3/dist-packages/urllib3/connectionpool.py&quot;, line 600, in urlopen
    chunked=chunked)
  File &quot;/usr/lib/python3/dist-packages/urllib3/connectionpool.py&quot;, line 354, in _make_request
    conn.request(method, url, **httplib_request_kw)
  File &quot;/usr/lib/python3.7/http/client.py&quot;, line 1244, in request
    self._send_request(method, url, body, headers, encode_chunked)
  File &quot;/usr/lib/python3.7/http/client.py&quot;, line 1290, in _send_request
    self.endheaders(body, encode_chunked=encode_chunked)
  File &quot;/usr/lib/python3.7/http/client.py&quot;, line 1239, in endheaders
    self._send_output(message_body, encode_chunked=encode_chunked)
  File &quot;/usr/lib/python3.7/http/client.py&quot;, line 1026, in _send_output
    self.send(msg)
  File &quot;/usr/lib/python3.7/http/client.py&quot;, line 966, in send
    self.connect()
  File &quot;/usr/lib/python3/dist-packages/urllib3/connection.py&quot;, line 181, in connect
    conn = self._new_conn()
  File &quot;/usr/lib/python3/dist-packages/urllib3/connection.py&quot;, line 168, in _new_conn
    self, &quot;Failed to establish a new connection: %s&quot; % e)
urllib3.exceptions.NewConnectionError: &lt;urllib3.connection.HTTPConnection object at 0x7ff43a708c50&gt;: Failed to establish a new connection: [Errno -2] Name or service not known

During handling of the above exception, another exception occurred:

Traceback (most recent call last):
  File &quot;/usr/lib/python3/dist-packages/requests/adapters.py&quot;, line 449, in send
    timeout=timeout
  File &quot;/usr/lib/python3/dist-packages/urllib3/connectionpool.py&quot;, line 638, in urlopen
    _stacktrace=sys.exc_info()[2])
  File &quot;/usr/lib/python3/dist-packages/urllib3/util/retry.py&quot;, line 398, in increment
    raise MaxRetryError(_pool, url, error or ResponseError(cause))
urllib3.exceptions.MaxRetryError: HTTPConnectionPool(host='earthquakes-uncc.herokuapp.com', port=80): Max retries exceeded with url: /eq/latest/10000?%7B'Accept:%20application/json'%7D (Caused by NewConnectionError('&lt;urllib3.connection.HTTPConnection object at 0x7ff43a708c50&gt;: Failed to establish a new connection: [Errno -2] Name or service not known'))

During handling of the above exception, another exception occurred:

Traceback (most recent call last):
  File &quot;GraphEQ.py&quot;, line 100, in &lt;module&gt;
    main()
  File &quot;GraphEQ.py&quot;, line 27, in main
    data = get_earthquake_usgs_data(10000)
  File &quot;/home/bridges-testing/.local/lib/python3.7/site-packages/bridges-3.1.1-py3.7.egg/bridges/data_src_dependent/data_source.py&quot;, line 154, in get_earthquake_usgs_data
  File &quot;/usr/lib/python3/dist-packages/requests/api.py&quot;, line 75, in get
    return request('get', url, params=params, **kwargs)
  File &quot;/usr/lib/python3/dist-packages/requests/api.py&quot;, line 60, in request
    return session.request(method=method, url=url, **kwargs)
  File &quot;/usr/lib/python3/dist-packages/requests/sessions.py&quot;, line 533, in request
    resp = self.send(prep, **send_kwargs)
  File &quot;/usr/lib/python3/dist-packages/requests/sessions.py&quot;, line 646, in send
    r = adapter.send(request, **kwargs)
  File &quot;/usr/lib/python3/dist-packages/requests/adapters.py&quot;, line 516, in send
    raise ConnectionError(e, request=request)
requests.exceptions.ConnectionError: HTTPConnectionPool(host='earthquakes-uncc.herokuapp.com', port=80): Max retries exceeded with url: /eq/latest/10000?%7B'Accept:%20application/json'%7D (Caused by NewConnectionError('&lt;urllib3.connection.HTTPConnection object at 0x7ff43a708c50&gt;: Failed to establish a new connection: [Errno -2] Name or service not known'))
could not run python_answer for assignment in ../assignmentdb/4-GraphEQ/python_answer
</code></pre>
</div>
    
    </div>
    <div id="pythonlog5" class="logdetails">
      <h2>Assignment 5 full log</h2>
    
<div class="failure">
<h3><span id="pythonlog5-runanswer">Run for Assignment 5</span></h3>
<pre><code>Guessing BST.py is the python file where main is

Traceback (most recent call last):
  File &quot;/usr/lib/python3/dist-packages/urllib3/connection.py&quot;, line 159, in _new_conn
    (self._dns_host, self.port), self.timeout, **extra_kw)
  File &quot;/usr/lib/python3/dist-packages/urllib3/util/connection.py&quot;, line 57, in create_connection
    for res in socket.getaddrinfo(host, port, family, socket.SOCK_STREAM):
  File &quot;/usr/lib/python3.7/socket.py&quot;, line 748, in getaddrinfo
    for res in _socket.getaddrinfo(host, port, family, type, proto, flags):
socket.gaierror: [Errno -2] Name or service not known

During handling of the above exception, another exception occurred:

Traceback (most recent call last):
  File &quot;/usr/lib/python3/dist-packages/urllib3/connectionpool.py&quot;, line 600, in urlopen
    chunked=chunked)
  File &quot;/usr/lib/python3/dist-packages/urllib3/connectionpool.py&quot;, line 354, in _make_request
    conn.request(method, url, **httplib_request_kw)
  File &quot;/usr/lib/python3.7/http/client.py&quot;, line 1244, in request
    self._send_request(method, url, body, headers, encode_chunked)
  File &quot;/usr/lib/python3.7/http/client.py&quot;, line 1290, in _send_request
    self.endheaders(body, encode_chunked=encode_chunked)
  File &quot;/usr/lib/python3.7/http/client.py&quot;, line 1239, in endheaders
    self._send_output(message_body, encode_chunked=encode_chunked)
  File &quot;/usr/lib/python3.7/http/client.py&quot;, line 1026, in _send_output
    self.send(msg)
  File &quot;/usr/lib/python3.7/http/client.py&quot;, line 966, in send
    self.connect()
  File &quot;/usr/lib/python3/dist-packages/urllib3/connection.py&quot;, line 181, in connect
    conn = self._new_conn()
  File &quot;/usr/lib/python3/dist-packages/urllib3/connection.py&quot;, line 168, in _new_conn
    self, &quot;Failed to establish a new connection: %s&quot; % e)
urllib3.exceptions.NewConnectionError: &lt;urllib3.connection.HTTPConnection object at 0x7fb12c0f4cc0&gt;: Failed to establish a new connection: [Errno -2] Name or service not known

During handling of the above exception, another exception occurred:

Traceback (most recent call last):
  File &quot;/usr/lib/python3/dist-packages/requests/adapters.py&quot;, line 449, in send
    timeout=timeout
  File &quot;/usr/lib/python3/dist-packages/urllib3/connectionpool.py&quot;, line 638, in urlopen
    _stacktrace=sys.exc_info()[2])
  File &quot;/usr/lib/python3/dist-packages/urllib3/util/retry.py&quot;, line 398, in increment
    raise MaxRetryError(_pool, url, error or ResponseError(cause))
urllib3.exceptions.MaxRetryError: HTTPConnectionPool(host='earthquakes-uncc.herokuapp.com', port=80): Max retries exceeded with url: /eq/latest/1000?%7B'Accept:%20application/json'%7D (Caused by NewConnectionError('&lt;urllib3.connection.HTTPConnection object at 0x7fb12c0f4cc0&gt;: Failed to establish a new connection: [Errno -2] Name or service not known'))

During handling of the above exception, another exception occurred:

Traceback (most recent call last):
  File &quot;BST.py&quot;, line 79, in &lt;module&gt;
    main()
  File &quot;BST.py&quot;, line 34, in main
    eq_list = get_earthquake_usgs_data(1000)
  File &quot;/home/bridges-testing/.local/lib/python3.7/site-packages/bridges-3.1.1-py3.7.egg/bridges/data_src_dependent/data_source.py&quot;, line 154, in get_earthquake_usgs_data
  File &quot;/usr/lib/python3/dist-packages/requests/api.py&quot;, line 75, in get
    return request('get', url, params=params, **kwargs)
  File &quot;/usr/lib/python3/dist-packages/requests/api.py&quot;, line 60, in request
    return session.request(method=method, url=url, **kwargs)
  File &quot;/usr/lib/python3/dist-packages/requests/sessions.py&quot;, line 533, in request
    resp = self.send(prep, **send_kwargs)
  File &quot;/usr/lib/python3/dist-packages/requests/sessions.py&quot;, line 646, in send
    r = adapter.send(request, **kwargs)
  File &quot;/usr/lib/python3/dist-packages/requests/adapters.py&quot;, line 516, in send
    raise ConnectionError(e, request=request)
requests.exceptions.ConnectionError: HTTPConnectionPool(host='earthquakes-uncc.herokuapp.com', port=80): Max retries exceeded with url: /eq/latest/1000?%7B'Accept:%20application/json'%7D (Caused by NewConnectionError('&lt;urllib3.connection.HTTPConnection object at 0x7fb12c0f4cc0&gt;: Failed to establish a new connection: [Errno -2] Name or service not known'))
could not run python_answer for assignment in ../assignmentdb/5-BstEq/python_answer
</code></pre>
</div>
    
    </div>
    <div id="pythonlog6" class="logdetails">
      <h2>Assignment 6 full log</h2>
    
<div class="failure">
<h3><span id="pythonlog6-runanswer">Run for Assignment 6</span></h3>
<pre><code>Guessing GridSquareFill.py is the python file where main is

RLE ran
Traceback (most recent call last):
  File &quot;/usr/lib/python3/dist-packages/urllib3/connection.py&quot;, line 159, in _new_conn
    (self._dns_host, self.port), self.timeout, **extra_kw)
  File &quot;/usr/lib/python3/dist-packages/urllib3/util/connection.py&quot;, line 57, in create_connection
    for res in socket.getaddrinfo(host, port, family, socket.SOCK_STREAM):
  File &quot;/usr/lib/python3.7/socket.py&quot;, line 748, in getaddrinfo
    for res in _socket.getaddrinfo(host, port, family, type, proto, flags):
socket.gaierror: [Errno -2] Name or service not known

During handling of the above exception, another exception occurred:

Traceback (most recent call last):
  File &quot;/usr/lib/python3/dist-packages/urllib3/connectionpool.py&quot;, line 600, in urlopen
    chunked=chunked)
  File &quot;/usr/lib/python3/dist-packages/urllib3/connectionpool.py&quot;, line 354, in _make_request
    conn.request(method, url, **httplib_request_kw)
  File &quot;/usr/lib/python3.7/http/client.py&quot;, line 1244, in request
    self._send_request(method, url, body, headers, encode_chunked)
  File &quot;/usr/lib/python3.7/http/client.py&quot;, line 1290, in _send_request
    self.endheaders(body, encode_chunked=encode_chunked)
  File &quot;/usr/lib/python3.7/http/client.py&quot;, line 1239, in endheaders
    self._send_output(message_body, encode_chunked=encode_chunked)
  File &quot;/usr/lib/python3.7/http/client.py&quot;, line 1026, in _send_output
    self.send(msg)
  File &quot;/usr/lib/python3.7/http/client.py&quot;, line 966, in send
    self.connect()
  File &quot;/usr/lib/python3/dist-packages/urllib3/connection.py&quot;, line 181, in connect
    conn = self._new_conn()
  File &quot;/usr/lib/python3/dist-packages/urllib3/connection.py&quot;, line 168, in _new_conn
    self, &quot;Failed to establish a new connection: %s&quot; % e)
urllib3.exceptions.NewConnectionError: &lt;urllib3.connection.HTTPConnection object at 0x7f5e8118be48&gt;: Failed to establish a new connection: [Errno -2] Name or service not known

During handling of the above exception, another exception occurred:

Traceback (most recent call last):
  File &quot;/usr/lib/python3/dist-packages/requests/adapters.py&quot;, line 449, in send
    timeout=timeout
  File &quot;/usr/lib/python3/dist-packages/urllib3/connectionpool.py&quot;, line 638, in urlopen
    _stacktrace=sys.exc_info()[2])
  File &quot;/usr/lib/python3/dist-packages/urllib3/util/retry.py&quot;, line 398, in increment
    raise MaxRetryError(_pool, url, error or ResponseError(cause))
urllib3.exceptions.MaxRetryError: HTTPConnectionPool(host='bridges-cs.herokuapp.com', port=80): Max retries exceeded with url: /assignments/206.00?apikey=1321549621122&amp;username=bridges_testing (Caused by NewConnectionError('&lt;urllib3.connection.HTTPConnection object at 0x7f5e8118be48&gt;: Failed to establish a new connection: [Errno -2] Name or service not known'))

During handling of the above exception, another exception occurred:

Traceback (most recent call last):
  File &quot;GridSquareFill.py&quot;, line 90, in &lt;module&gt;
    main()
  File &quot;GridSquareFill.py&quot;, line 87, in main
    bridges.visualize()
  File &quot;/home/bridges-testing/.local/lib/python3.7/site-packages/bridges-3.1.1-py3.7.egg/bridges/bridges.py&quot;, line 174, in visualize
  File &quot;/home/bridges-testing/.local/lib/python3.7/site-packages/bridges-3.1.1-py3.7.egg/bridges/connector.py&quot;, line 64, in post
  File &quot;/usr/lib/python3/dist-packages/requests/api.py&quot;, line 116, in post
    return request('post', url, data=data, json=json, **kwargs)
  File &quot;/usr/lib/python3/dist-packages/requests/api.py&quot;, line 60, in request
    return session.request(method=method, url=url, **kwargs)
  File &quot;/usr/lib/python3/dist-packages/requests/sessions.py&quot;, line 533, in request
    resp = self.send(prep, **send_kwargs)
  File &quot;/usr/lib/python3/dist-packages/requests/sessions.py&quot;, line 646, in send
    r = adapter.send(request, **kwargs)
  File &quot;/usr/lib/python3/dist-packages/requests/adapters.py&quot;, line 516, in send
    raise ConnectionError(e, request=request)
requests.exceptions.ConnectionError: HTTPConnectionPool(host='bridges-cs.herokuapp.com', port=80): Max retries exceeded with url: /assignments/206.00?apikey=1321549621122&amp;username=bridges_testing (Caused by NewConnectionError('&lt;urllib3.connection.HTTPConnection object at 0x7f5e8118be48&gt;: Failed to establish a new connection: [Errno -2] Name or service not known'))
could not run python_answer for assignment in ../assignmentdb/6-GridSquareFill/python_answer
</code></pre>
</div>
    
    </div>
    <div id="pythonlog7" class="logdetails">
      <h2>Assignment 7 full log</h2>
    
<div class="failure">
<h3><span id="pythonlog7-runanswer">Run for Assignment 7</span></h3>
<pre><code>Guessing GridLyrics.py is the python file where main is

Traceback (most recent call last):
  File &quot;/usr/lib/python3/dist-packages/urllib3/connection.py&quot;, line 159, in _new_conn
    (self._dns_host, self.port), self.timeout, **extra_kw)
  File &quot;/usr/lib/python3/dist-packages/urllib3/util/connection.py&quot;, line 57, in create_connection
    for res in socket.getaddrinfo(host, port, family, socket.SOCK_STREAM):
  File &quot;/usr/lib/python3.7/socket.py&quot;, line 748, in getaddrinfo
    for res in _socket.getaddrinfo(host, port, family, type, proto, flags):
socket.gaierror: [Errno -2] Name or service not known

During handling of the above exception, another exception occurred:

Traceback (most recent call last):
  File &quot;/usr/lib/python3/dist-packages/urllib3/connectionpool.py&quot;, line 600, in urlopen
    chunked=chunked)
  File &quot;/usr/lib/python3/dist-packages/urllib3/connectionpool.py&quot;, line 354, in _make_request
    conn.request(method, url, **httplib_request_kw)
  File &quot;/usr/lib/python3.7/http/client.py&quot;, line 1244, in request
    self._send_request(method, url, body, headers, encode_chunked)
  File &quot;/usr/lib/python3.7/http/client.py&quot;, line 1290, in _send_request
    self.endheaders(body, encode_chunked=encode_chunked)
  File &quot;/usr/lib/python3.7/http/client.py&quot;, line 1239, in endheaders
    self._send_output(message_body, encode_chunked=encode_chunked)
  File &quot;/usr/lib/python3.7/http/client.py&quot;, line 1026, in _send_output
    self.send(msg)
  File &quot;/usr/lib/python3.7/http/client.py&quot;, line 966, in send
    self.connect()
  File &quot;/usr/lib/python3/dist-packages/urllib3/connection.py&quot;, line 181, in connect
    conn = self._new_conn()
  File &quot;/usr/lib/python3/dist-packages/urllib3/connection.py&quot;, line 168, in _new_conn
    self, &quot;Failed to establish a new connection: %s&quot; % e)
urllib3.exceptions.NewConnectionError: &lt;urllib3.connection.HTTPConnection object at 0x7fdf5a78b9e8&gt;: Failed to establish a new connection: [Errno -2] Name or service not known

During handling of the above exception, another exception occurred:

Traceback (most recent call last):
  File &quot;/usr/lib/python3/dist-packages/requests/adapters.py&quot;, line 449, in send
    timeout=timeout
  File &quot;/usr/lib/python3/dist-packages/urllib3/connectionpool.py&quot;, line 638, in urlopen
    _stacktrace=sys.exc_info()[2])
  File &quot;/usr/lib/python3/dist-packages/urllib3/util/retry.py&quot;, line 398, in increment
    raise MaxRetryError(_pool, url, error or ResponseError(cause))
urllib3.exceptions.MaxRetryError: HTTPConnectionPool(host='bridgesdata.herokuapp.com', port=80): Max retries exceeded with url: /api/songs/find/Delicate?artistName=Taylor%20Swift&amp;%7B'Accept:%20application/json'%7D (Caused by NewConnectionError('&lt;urllib3.connection.HTTPConnection object at 0x7fdf5a78b9e8&gt;: Failed to establish a new connection: [Errno -2] Name or service not known'))

During handling of the above exception, another exception occurred:

Traceback (most recent call last):
  File &quot;GridLyrics.py&quot;, line 58, in &lt;module&gt;
    main()
  File &quot;GridLyrics.py&quot;, line 31, in main
    so = get_song(&quot;Delicate&quot;, &quot;Taylor Swift&quot;)
  File &quot;/home/bridges-testing/.local/lib/python3.7/site-packages/bridges-3.1.1-py3.7.egg/bridges/data_src_dependent/data_source.py&quot;, line 333, in get_song
  File &quot;/usr/lib/python3/dist-packages/requests/api.py&quot;, line 75, in get
    return request('get', url, params=params, **kwargs)
  File &quot;/usr/lib/python3/dist-packages/requests/api.py&quot;, line 60, in request
    return session.request(method=method, url=url, **kwargs)
  File &quot;/usr/lib/python3/dist-packages/requests/sessions.py&quot;, line 533, in request
    resp = self.send(prep, **send_kwargs)
  File &quot;/usr/lib/python3/dist-packages/requests/sessions.py&quot;, line 646, in send
    r = adapter.send(request, **kwargs)
  File &quot;/usr/lib/python3/dist-packages/requests/adapters.py&quot;, line 516, in send
    raise ConnectionError(e, request=request)
requests.exceptions.ConnectionError: HTTPConnectionPool(host='bridgesdata.herokuapp.com', port=80): Max retries exceeded with url: /api/songs/find/Delicate?artistName=Taylor%20Swift&amp;%7B'Accept:%20application/json'%7D (Caused by NewConnectionError('&lt;urllib3.connection.HTTPConnection object at 0x7fdf5a78b9e8&gt;: Failed to establish a new connection: [Errno -2] Name or service not known'))
could not run python_answer for assignment in ../assignmentdb/7-GridLyrics/python_answer
</code></pre>
</div>
    
    </div>
    <div id="pythonlog8" class="logdetails">
      <h2>Assignment 8 full log</h2>
    
<div class="failure">
<h3><span id="pythonlog8-runanswer">Run for Assignment 8</span></h3>
<pre><code>Guessing PQBook.py is the python file where main is

Traceback (most recent call last):
  File &quot;/usr/lib/python3/dist-packages/urllib3/connection.py&quot;, line 159, in _new_conn
    (self._dns_host, self.port), self.timeout, **extra_kw)
  File &quot;/usr/lib/python3/dist-packages/urllib3/util/connection.py&quot;, line 57, in create_connection
    for res in socket.getaddrinfo(host, port, family, socket.SOCK_STREAM):
  File &quot;/usr/lib/python3.7/socket.py&quot;, line 748, in getaddrinfo
    for res in _socket.getaddrinfo(host, port, family, type, proto, flags):
socket.gaierror: [Errno -2] Name or service not known

During handling of the above exception, another exception occurred:

Traceback (most recent call last):
  File &quot;/usr/lib/python3/dist-packages/urllib3/connectionpool.py&quot;, line 600, in urlopen
    chunked=chunked)
  File &quot;/usr/lib/python3/dist-packages/urllib3/connectionpool.py&quot;, line 354, in _make_request
    conn.request(method, url, **httplib_request_kw)
  File &quot;/usr/lib/python3.7/http/client.py&quot;, line 1244, in request
    self._send_request(method, url, body, headers, encode_chunked)
  File &quot;/usr/lib/python3.7/http/client.py&quot;, line 1290, in _send_request
    self.endheaders(body, encode_chunked=encode_chunked)
  File &quot;/usr/lib/python3.7/http/client.py&quot;, line 1239, in endheaders
    self._send_output(message_body, encode_chunked=encode_chunked)
  File &quot;/usr/lib/python3.7/http/client.py&quot;, line 1026, in _send_output
    self.send(msg)
  File &quot;/usr/lib/python3.7/http/client.py&quot;, line 966, in send
    self.connect()
  File &quot;/usr/lib/python3/dist-packages/urllib3/connection.py&quot;, line 181, in connect
    conn = self._new_conn()
  File &quot;/usr/lib/python3/dist-packages/urllib3/connection.py&quot;, line 168, in _new_conn
    self, &quot;Failed to establish a new connection: %s&quot; % e)
urllib3.exceptions.NewConnectionError: &lt;urllib3.connection.HTTPConnection object at 0x7f4b3496def0&gt;: Failed to establish a new connection: [Errno -2] Name or service not known

During handling of the above exception, another exception occurred:

Traceback (most recent call last):
  File &quot;/usr/lib/python3/dist-packages/requests/adapters.py&quot;, line 449, in send
    timeout=timeout
  File &quot;/usr/lib/python3/dist-packages/urllib3/connectionpool.py&quot;, line 638, in urlopen
    _stacktrace=sys.exc_info()[2])
  File &quot;/usr/lib/python3/dist-packages/urllib3/util/retry.py&quot;, line 398, in increment
    raise MaxRetryError(_pool, url, error or ResponseError(cause))
urllib3.exceptions.MaxRetryError: HTTPConnectionPool(host='bridgesdata.herokuapp.com', port=80): Max retries exceeded with url: /api/shakespeare//poems?format=simple&amp;%7B'Accept:%20application/json'%7D (Caused by NewConnectionError('&lt;urllib3.connection.HTTPConnection object at 0x7f4b3496def0&gt;: Failed to establish a new connection: [Errno -2] Name or service not known'))

During handling of the above exception, another exception occurred:

Traceback (most recent call last):
  File &quot;PQBook.py&quot;, line 62, in &lt;module&gt;
    main()
  File &quot;PQBook.py&quot;, line 19, in main
    shksp_list = get_shakespeare_data(&quot;poems&quot;, True)
  File &quot;/home/bridges-testing/.local/lib/python3.7/site-packages/bridges-3.1.1-py3.7.egg/bridges/data_src_dependent/data_source.py&quot;, line 193, in get_shakespeare_data
  File &quot;/usr/lib/python3/dist-packages/requests/api.py&quot;, line 75, in get
    return request('get', url, params=params, **kwargs)
  File &quot;/usr/lib/python3/dist-packages/requests/api.py&quot;, line 60, in request
    return session.request(method=method, url=url, **kwargs)
  File &quot;/usr/lib/python3/dist-packages/requests/sessions.py&quot;, line 533, in request
    resp = self.send(prep, **send_kwargs)
  File &quot;/usr/lib/python3/dist-packages/requests/sessions.py&quot;, line 646, in send
    r = adapter.send(request, **kwargs)
  File &quot;/usr/lib/python3/dist-packages/requests/adapters.py&quot;, line 516, in send
    raise ConnectionError(e, request=request)
requests.exceptions.ConnectionError: HTTPConnectionPool(host='bridgesdata.herokuapp.com', port=80): Max retries exceeded with url: /api/shakespeare//poems?format=simple&amp;%7B'Accept:%20application/json'%7D (Caused by NewConnectionError('&lt;urllib3.connection.HTTPConnection object at 0x7f4b3496def0&gt;: Failed to establish a new connection: [Errno -2] Name or service not known'))
could not run python_answer for assignment in ../assignmentdb/8-PQBook/python_answer
</code></pre>
</div>
    
    </div>
    <div id="pythonlog9" class="logdetails">
      <h2>Assignment 9 full log</h2>
    
<div class="failure">
<h3><span id="pythonlog9-runanswer">Run for Assignment 9</span></h3>
<pre><code>Guessing ShortestPathOSM.py is the python file where main is

Traceback (most recent call last):
  File &quot;/usr/lib/python3/dist-packages/urllib3/connection.py&quot;, line 159, in _new_conn
    (self._dns_host, self.port), self.timeout, **extra_kw)
  File &quot;/usr/lib/python3/dist-packages/urllib3/util/connection.py&quot;, line 57, in create_connection
    for res in socket.getaddrinfo(host, port, family, socket.SOCK_STREAM):
  File &quot;/usr/lib/python3.7/socket.py&quot;, line 748, in getaddrinfo
    for res in _socket.getaddrinfo(host, port, family, type, proto, flags):
socket.gaierror: [Errno -2] Name or service not known

During handling of the above exception, another exception occurred:

Traceback (most recent call last):
  File &quot;/usr/lib/python3/dist-packages/urllib3/connectionpool.py&quot;, line 600, in urlopen
    chunked=chunked)
  File &quot;/usr/lib/python3/dist-packages/urllib3/connectionpool.py&quot;, line 354, in _make_request
    conn.request(method, url, **httplib_request_kw)
  File &quot;/usr/lib/python3.7/http/client.py&quot;, line 1244, in request
    self._send_request(method, url, body, headers, encode_chunked)
  File &quot;/usr/lib/python3.7/http/client.py&quot;, line 1290, in _send_request
    self.endheaders(body, encode_chunked=encode_chunked)
  File &quot;/usr/lib/python3.7/http/client.py&quot;, line 1239, in endheaders
    self._send_output(message_body, encode_chunked=encode_chunked)
  File &quot;/usr/lib/python3.7/http/client.py&quot;, line 1026, in _send_output
    self.send(msg)
  File &quot;/usr/lib/python3.7/http/client.py&quot;, line 966, in send
    self.connect()
  File &quot;/usr/lib/python3/dist-packages/urllib3/connection.py&quot;, line 181, in connect
    conn = self._new_conn()
  File &quot;/usr/lib/python3/dist-packages/urllib3/connection.py&quot;, line 168, in _new_conn
    self, &quot;Failed to establish a new connection: %s&quot; % e)
urllib3.exceptions.NewConnectionError: &lt;urllib3.connection.HTTPConnection object at 0x7f079cc7ae80&gt;: Failed to establish a new connection: [Errno -2] Name or service not known

During handling of the above exception, another exception occurred:

Traceback (most recent call last):
  File &quot;/usr/lib/python3/dist-packages/requests/adapters.py&quot;, line 449, in send
    timeout=timeout
  File &quot;/usr/lib/python3/dist-packages/urllib3/connectionpool.py&quot;, line 638, in urlopen
    _stacktrace=sys.exc_info()[2])
  File &quot;/usr/lib/python3/dist-packages/urllib3/util/retry.py&quot;, line 398, in increment
    raise MaxRetryError(_pool, url, error or ResponseError(cause))
urllib3.exceptions.MaxRetryError: HTTPConnectionPool(host='cci-bridges-osm.uncc.edu', port=80): Max retries exceeded with url: /hash?location=Charlotte,%20North%20Carolina&amp;level=default (Caused by NewConnectionError('&lt;urllib3.connection.HTTPConnection object at 0x7f079cc7ae80&gt;: Failed to establish a new connection: [Errno -2] Name or service not known'))

During handling of the above exception, another exception occurred:

Traceback (most recent call last):
  File &quot;ShortestPathOSM.py&quot;, line 165, in &lt;module&gt;
    main()
  File &quot;ShortestPathOSM.py&quot;, line 121, in main
    osm_data = data_source.get_osm_data(&quot;Charlotte, North Carolina&quot;, &quot;default&quot;)
  File &quot;/home/bridges-testing/.local/lib/python3.7/site-packages/bridges-3.1.1-py3.7.egg/bridges/data_src_dependent/data_source.py&quot;, line 586, in get_osm_data
  File &quot;/home/bridges-testing/.local/lib/python3.7/site-packages/bridges-3.1.1-py3.7.egg/bridges/data_src_dependent/data_source.py&quot;, line 538, in osm_server_request
  File &quot;/usr/lib/python3/dist-packages/requests/api.py&quot;, line 75, in get
    return request('get', url, params=params, **kwargs)
  File &quot;/usr/lib/python3/dist-packages/requests/api.py&quot;, line 60, in request
    return session.request(method=method, url=url, **kwargs)
  File &quot;/usr/lib/python3/dist-packages/requests/sessions.py&quot;, line 533, in request
    resp = self.send(prep, **send_kwargs)
  File &quot;/usr/lib/python3/dist-packages/requests/sessions.py&quot;, line 646, in send
    r = adapter.send(request, **kwargs)
  File &quot;/usr/lib/python3/dist-packages/requests/adapters.py&quot;, line 516, in send
    raise ConnectionError(e, request=request)
requests.exceptions.ConnectionError: HTTPConnectionPool(host='cci-bridges-osm.uncc.edu', port=80): Max retries exceeded with url: /hash?location=Charlotte,%20North%20Carolina&amp;level=default (Caused by NewConnectionError('&lt;urllib3.connection.HTTPConnection object at 0x7f079cc7ae80&gt;: Failed to establish a new connection: [Errno -2] Name or service not known'))
could not run python_answer for assignment in ../assignmentdb/9-ShortestPathOSM/python_answer
</code></pre>
</div>
    
    </div>
    <div id="pythonlog10" class="logdetails">
      <h2>Assignment 10 full log</h2>
    
<div class="failure">
<h3><span id="pythonlog10-runanswer">Run for Assignment 10</span></h3>
<pre><code>Guessing HurricaneTracker.py is the python file where main is

Traceback (most recent call last):
  File &quot;/usr/lib/python3/dist-packages/urllib3/connection.py&quot;, line 159, in _new_conn
    (self._dns_host, self.port), self.timeout, **extra_kw)
  File &quot;/usr/lib/python3/dist-packages/urllib3/util/connection.py&quot;, line 57, in create_connection
    for res in socket.getaddrinfo(host, port, family, socket.SOCK_STREAM):
  File &quot;/usr/lib/python3.7/socket.py&quot;, line 748, in getaddrinfo
    for res in _socket.getaddrinfo(host, port, family, type, proto, flags):
socket.gaierror: [Errno -2] Name or service not known

During handling of the above exception, another exception occurred:

Traceback (most recent call last):
  File &quot;/usr/lib/python3/dist-packages/urllib3/connectionpool.py&quot;, line 600, in urlopen
    chunked=chunked)
  File &quot;/usr/lib/python3/dist-packages/urllib3/connectionpool.py&quot;, line 354, in _make_request
    conn.request(method, url, **httplib_request_kw)
  File &quot;/usr/lib/python3.7/http/client.py&quot;, line 1244, in request
    self._send_request(method, url, body, headers, encode_chunked)
  File &quot;/usr/lib/python3.7/http/client.py&quot;, line 1290, in _send_request
    self.endheaders(body, encode_chunked=encode_chunked)
  File &quot;/usr/lib/python3.7/http/client.py&quot;, line 1239, in endheaders
    self._send_output(message_body, encode_chunked=encode_chunked)
  File &quot;/usr/lib/python3.7/http/client.py&quot;, line 1026, in _send_output
    self.send(msg)
  File &quot;/usr/lib/python3.7/http/client.py&quot;, line 966, in send
    self.connect()
  File &quot;/usr/lib/python3/dist-packages/urllib3/connection.py&quot;, line 181, in connect
    conn = self._new_conn()
  File &quot;/usr/lib/python3/dist-packages/urllib3/connection.py&quot;, line 168, in _new_conn
    self, &quot;Failed to establish a new connection: %s&quot; % e)
urllib3.exceptions.NewConnectionError: &lt;urllib3.connection.HTTPConnection object at 0x7f723ad406a0&gt;: Failed to establish a new connection: [Errno -2] Name or service not known

During handling of the above exception, another exception occurred:

Traceback (most recent call last):
  File &quot;/usr/lib/python3/dist-packages/requests/adapters.py&quot;, line 449, in send
    timeout=timeout
  File &quot;/usr/lib/python3/dist-packages/urllib3/connectionpool.py&quot;, line 638, in urlopen
    _stacktrace=sys.exc_info()[2])
  File &quot;/usr/lib/python3/dist-packages/urllib3/util/retry.py&quot;, line 398, in increment
    raise MaxRetryError(_pool, url, error or ResponseError(cause))
urllib3.exceptions.MaxRetryError: HTTPConnectionPool(host='bridges-cs.herokuapp.com', port=80): Max retries exceeded with url: /assignments/210.00?apikey=1321549621122&amp;username=bridges_testing (Caused by NewConnectionError('&lt;urllib3.connection.HTTPConnection object at 0x7f723ad406a0&gt;: Failed to establish a new connection: [Errno -2] Name or service not known'))

During handling of the above exception, another exception occurred:

Traceback (most recent call last):
  File &quot;HurricaneTracker.py&quot;, line 84, in &lt;module&gt;
    main()
  File &quot;HurricaneTracker.py&quot;, line 81, in main
    bridges.visualize()
  File &quot;/home/bridges-testing/.local/lib/python3.7/site-packages/bridges-3.1.1-py3.7.egg/bridges/bridges.py&quot;, line 174, in visualize
  File &quot;/home/bridges-testing/.local/lib/python3.7/site-packages/bridges-3.1.1-py3.7.egg/bridges/connector.py&quot;, line 64, in post
  File &quot;/usr/lib/python3/dist-packages/requests/api.py&quot;, line 116, in post
    return request('post', url, data=data, json=json, **kwargs)
  File &quot;/usr/lib/python3/dist-packages/requests/api.py&quot;, line 60, in request
    return session.request(method=method, url=url, **kwargs)
  File &quot;/usr/lib/python3/dist-packages/requests/sessions.py&quot;, line 533, in request
    resp = self.send(prep, **send_kwargs)
  File &quot;/usr/lib/python3/dist-packages/requests/sessions.py&quot;, line 646, in send
    r = adapter.send(request, **kwargs)
  File &quot;/usr/lib/python3/dist-packages/requests/adapters.py&quot;, line 516, in send
    raise ConnectionError(e, request=request)
requests.exceptions.ConnectionError: HTTPConnectionPool(host='bridges-cs.herokuapp.com', port=80): Max retries exceeded with url: /assignments/210.00?apikey=1321549621122&amp;username=bridges_testing (Caused by NewConnectionError('&lt;urllib3.connection.HTTPConnection object at 0x7f723ad406a0&gt;: Failed to establish a new connection: [Errno -2] Name or service not known'))
could not run python_answer for assignment in ../assignmentdb/10-HurricaneTracker/python_answer
</code></pre>
</div>
    
    </div>
    <div id="pythonlog11" class="logdetails">
      <h2>Assignment 11 full log</h2>
    
<div class="failure">
<h3><span id="pythonlog11-runanswer">Run for Assignment 11</span></h3>
<pre><code>Guessing 2048Game.py is the python file where main is

Traceback (most recent call last):
  File &quot;2048Game.py&quot;, line 244, in &lt;module&gt;
    main()
  File &quot;2048Game.py&quot;, line 238, in main
    game = Game2048(211, &quot;BRIDGES_USER_ID&quot;, &quot;BRIDGES_API_KEY&quot;)
  File &quot;2048Game.py&quot;, line 42, in __init__
    super(Game2048, self).__init__(assid, login, apikey, 24, 24)
  File &quot;/home/bridges-testing/.local/lib/python3.7/site-packages/bridges-3.1.1-py3.7.egg/bridges/non_blocking_game.py&quot;, line 105, in __init__
  File &quot;/home/bridges-testing/.local/lib/python3.7/site-packages/bridges-3.1.1-py3.7.egg/bridges/gamebase.py&quot;, line 16, in __init__
  File &quot;/home/bridges-testing/.local/lib/python3.7/site-packages/bridges-3.1.1-py3.7.egg/bridges/gamebase.py&quot;, line 33, in game_base_init
  File &quot;/home/bridges-testing/.local/lib/python3.7/site-packages/bridges-3.1.1-py3.7.egg/bridges/socket_connection.py&quot;, line 20, in setup_connection
  File &quot;/home/bridges-testing/.local/lib/python3.7/site-packages/python_socketio-4.6.0-py3.7.egg/socketio/client.py&quot;, line 282, in connect
    six.raise_from(exceptions.ConnectionError(exc.args[0]), None)
  File &quot;&lt;string&gt;&quot;, line 3, in raise_from
socketio.exceptions.ConnectionError: Connection error
could not run python_answer for assignment in ../assignmentdb/11-2048Game/python_answer
</code></pre>
</div>
    
    </div>
    <div id="pythonlog12" class="logdetails">
      <h2>Assignment 12 full log</h2>
    
<div class="failure">
<h3><span id="pythonlog12-runanswer">Run for Assignment 12</span></h3>
<pre><code>Guessing AStarMaze.py is the python file where main is

Traceback (most recent call last):
  File &quot;AStarMaze.py&quot;, line 214, in &lt;module&gt;
    main()
  File &quot;AStarMaze.py&quot;, line 208, in main
    game = AStarMaze(212, &quot;BRIDGES_USER_ID&quot;, &quot;BRIDGES_API_KEY&quot;)
  File &quot;AStarMaze.py&quot;, line 35, in __init__
    super(AStarMaze, self).__init__(assid, login, apikey, 31, 31)
  File &quot;/home/bridges-testing/.local/lib/python3.7/site-packages/bridges-3.1.1-py3.7.egg/bridges/non_blocking_game.py&quot;, line 105, in __init__
  File &quot;/home/bridges-testing/.local/lib/python3.7/site-packages/bridges-3.1.1-py3.7.egg/bridges/gamebase.py&quot;, line 16, in __init__
  File &quot;/home/bridges-testing/.local/lib/python3.7/site-packages/bridges-3.1.1-py3.7.egg/bridges/gamebase.py&quot;, line 33, in game_base_init
  File &quot;/home/bridges-testing/.local/lib/python3.7/site-packages/bridges-3.1.1-py3.7.egg/bridges/socket_connection.py&quot;, line 20, in setup_connection
  File &quot;/home/bridges-testing/.local/lib/python3.7/site-packages/python_socketio-4.6.0-py3.7.egg/socketio/client.py&quot;, line 282, in connect
    six.raise_from(exceptions.ConnectionError(exc.args[0]), None)
  File &quot;&lt;string&gt;&quot;, line 3, in raise_from
socketio.exceptions.ConnectionError: Connection error
could not run python_answer for assignment in ../assignmentdb/12-AStarMaze/python_answer
</code></pre>
</div>
    
    </div>
    <div id="pythonlog13" class="logdetails">
      <h2>Assignment 13 full log</h2>
    
<div class="failure">
<h3><span id="pythonlog13-runanswer">Run for Assignment 13</span></h3>
<pre><code>Guessing InfiniteRunner.py is the python file where main is

Traceback (most recent call last):
  File &quot;InfiniteRunner.py&quot;, line 134, in &lt;module&gt;
    main()
  File &quot;InfiniteRunner.py&quot;, line 128, in main
    game = Runner(213, &quot;BRIDGES_USER_ID&quot;, &quot;BRIDGES_API_KEY&quot;)
  File &quot;InfiniteRunner.py&quot;, line 68, in __init__
    super(Runner, self).__init__(assid, login, apikey, 24, 24)
  File &quot;/home/bridges-testing/.local/lib/python3.7/site-packages/bridges-3.1.1-py3.7.egg/bridges/non_blocking_game.py&quot;, line 105, in __init__
  File &quot;/home/bridges-testing/.local/lib/python3.7/site-packages/bridges-3.1.1-py3.7.egg/bridges/gamebase.py&quot;, line 16, in __init__
  File &quot;/home/bridges-testing/.local/lib/python3.7/site-packages/bridges-3.1.1-py3.7.egg/bridges/gamebase.py&quot;, line 33, in game_base_init
  File &quot;/home/bridges-testing/.local/lib/python3.7/site-packages/bridges-3.1.1-py3.7.egg/bridges/socket_connection.py&quot;, line 20, in setup_connection
  File &quot;/home/bridges-testing/.local/lib/python3.7/site-packages/python_socketio-4.6.0-py3.7.egg/socketio/client.py&quot;, line 282, in connect
    six.raise_from(exceptions.ConnectionError(exc.args[0]), None)
  File &quot;&lt;string&gt;&quot;, line 3, in raise_from
socketio.exceptions.ConnectionError: Connection error
could not run python_answer for assignment in ../assignmentdb/13-InfiniteRunner/python_answer
</code></pre>
</div>
    
    </div>
    <div id="pythonlog14" class="logdetails">
      <h2>Assignment 14 full log</h2>
    
<div class="failure">
<h3><span id="pythonlog14-runanswer">Run for Assignment 14</span></h3>
<pre><code>Guessing SpreadingFire.py is the python file where main is

Traceback (most recent call last):
  File &quot;SpreadingFire.py&quot;, line 146, in &lt;module&gt;
    main()
  File &quot;SpreadingFire.py&quot;, line 141, in main
    my_game = SpreadingFire(14, &quot;BRIDGES_USER_ID&quot;, &quot;BRIDGES_API_KEY&quot;, 30, 30)
  File &quot;SpreadingFire.py&quot;, line 74, in __init__
    super(SpreadingFire, self).__init__(assid, login, apikey, cols, rows)
  File &quot;/home/bridges-testing/.local/lib/python3.7/site-packages/bridges-3.1.1-py3.7.egg/bridges/non_blocking_game.py&quot;, line 105, in __init__
  File &quot;/home/bridges-testing/.local/lib/python3.7/site-packages/bridges-3.1.1-py3.7.egg/bridges/gamebase.py&quot;, line 16, in __init__
  File &quot;/home/bridges-testing/.local/lib/python3.7/site-packages/bridges-3.1.1-py3.7.egg/bridges/gamebase.py&quot;, line 33, in game_base_init
  File &quot;/home/bridges-testing/.local/lib/python3.7/site-packages/bridges-3.1.1-py3.7.egg/bridges/socket_connection.py&quot;, line 20, in setup_connection
  File &quot;/home/bridges-testing/.local/lib/python3.7/site-packages/python_socketio-4.6.0-py3.7.egg/socketio/client.py&quot;, line 282, in connect
    six.raise_from(exceptions.ConnectionError(exc.args[0]), None)
  File &quot;&lt;string&gt;&quot;, line 3, in raise_from
socketio.exceptions.ConnectionError: Connection error
could not run python_answer for assignment in ../assignmentdb/14-SpreadingFire/python_answer
</code></pre>
</div>
    
    </div>
    <div id="pythonlog15" class="logdetails">
      <h2>Assignment 15 full log</h2>
    
<div class="failure">
<h3><span id="pythonlog15-runanswer">Run for Assignment 15</span></h3>
<pre><code>Guessing FallingSand.py is the python file where main is

Traceback (most recent call last):
  File &quot;FallingSand.py&quot;, line 191, in &lt;module&gt;
    main()
  File &quot;FallingSand.py&quot;, line 186, in main
    my_game = FallingSand(215, &quot;BRIDGES_USER_ID&quot;, &quot;BRIDGES_API_KEY&quot;, 30, 30)
  File &quot;FallingSand.py&quot;, line 177, in __init__
    super(FallingSand, self).__init__(assid, login, apikey, cols, rows)
  File &quot;/home/bridges-testing/.local/lib/python3.7/site-packages/bridges-3.1.1-py3.7.egg/bridges/non_blocking_game.py&quot;, line 105, in __init__
  File &quot;/home/bridges-testing/.local/lib/python3.7/site-packages/bridges-3.1.1-py3.7.egg/bridges/gamebase.py&quot;, line 16, in __init__
  File &quot;/home/bridges-testing/.local/lib/python3.7/site-packages/bridges-3.1.1-py3.7.egg/bridges/gamebase.py&quot;, line 33, in game_base_init
  File &quot;/home/bridges-testing/.local/lib/python3.7/site-packages/bridges-3.1.1-py3.7.egg/bridges/socket_connection.py&quot;, line 20, in setup_connection
  File &quot;/home/bridges-testing/.local/lib/python3.7/site-packages/python_socketio-4.6.0-py3.7.egg/socketio/client.py&quot;, line 282, in connect
    six.raise_from(exceptions.ConnectionError(exc.args[0]), None)
  File &quot;&lt;string&gt;&quot;, line 3, in raise_from
socketio.exceptions.ConnectionError: Connection error
could not run python_answer for assignment in ../assignmentdb/15-FallingSand/python_answer
</code></pre>
</div>
    
    </div>
    <div id="pythonlog16" class="logdetails">
      <h2>Assignment 16 full log</h2>
    
<div class="failure">
<h3><span id="pythonlog16-runanswer">Run for Assignment 16</span></h3>
<pre><code>Guessing ImagePuzzle.py is the python file where main is

RLE ran
Traceback (most recent call last):
  File &quot;/usr/lib/python3/dist-packages/urllib3/connection.py&quot;, line 159, in _new_conn
    (self._dns_host, self.port), self.timeout, **extra_kw)
  File &quot;/usr/lib/python3/dist-packages/urllib3/util/connection.py&quot;, line 57, in create_connection
    for res in socket.getaddrinfo(host, port, family, socket.SOCK_STREAM):
  File &quot;/usr/lib/python3.7/socket.py&quot;, line 748, in getaddrinfo
    for res in _socket.getaddrinfo(host, port, family, type, proto, flags):
socket.gaierror: [Errno -2] Name or service not known

During handling of the above exception, another exception occurred:

Traceback (most recent call last):
  File &quot;/usr/lib/python3/dist-packages/urllib3/connectionpool.py&quot;, line 600, in urlopen
    chunked=chunked)
  File &quot;/usr/lib/python3/dist-packages/urllib3/connectionpool.py&quot;, line 354, in _make_request
    conn.request(method, url, **httplib_request_kw)
  File &quot;/usr/lib/python3.7/http/client.py&quot;, line 1244, in request
    self._send_request(method, url, body, headers, encode_chunked)
  File &quot;/usr/lib/python3.7/http/client.py&quot;, line 1290, in _send_request
    self.endheaders(body, encode_chunked=encode_chunked)
  File &quot;/usr/lib/python3.7/http/client.py&quot;, line 1239, in endheaders
    self._send_output(message_body, encode_chunked=encode_chunked)
  File &quot;/usr/lib/python3.7/http/client.py&quot;, line 1026, in _send_output
    self.send(msg)
  File &quot;/usr/lib/python3.7/http/client.py&quot;, line 966, in send
    self.connect()
  File &quot;/usr/lib/python3/dist-packages/urllib3/connection.py&quot;, line 181, in connect
    conn = self._new_conn()
  File &quot;/usr/lib/python3/dist-packages/urllib3/connection.py&quot;, line 168, in _new_conn
    self, &quot;Failed to establish a new connection: %s&quot; % e)
urllib3.exceptions.NewConnectionError: &lt;urllib3.connection.HTTPConnection object at 0x7f642e47fbe0&gt;: Failed to establish a new connection: [Errno -2] Name or service not known

During handling of the above exception, another exception occurred:

Traceback (most recent call last):
  File &quot;/usr/lib/python3/dist-packages/requests/adapters.py&quot;, line 449, in send
    timeout=timeout
  File &quot;/usr/lib/python3/dist-packages/urllib3/connectionpool.py&quot;, line 638, in urlopen
    _stacktrace=sys.exc_info()[2])
  File &quot;/usr/lib/python3/dist-packages/urllib3/util/retry.py&quot;, line 398, in increment
    raise MaxRetryError(_pool, url, error or ResponseError(cause))
urllib3.exceptions.MaxRetryError: HTTPConnectionPool(host='bridges-cs.herokuapp.com', port=80): Max retries exceeded with url: /assignments/216.00?apikey=1321549621122&amp;username=bridges_testing (Caused by NewConnectionError('&lt;urllib3.connection.HTTPConnection object at 0x7f642e47fbe0&gt;: Failed to establish a new connection: [Errno -2] Name or service not known'))

During handling of the above exception, another exception occurred:

Traceback (most recent call last):
  File &quot;ImagePuzzle.py&quot;, line 86, in &lt;module&gt;
    main()
  File &quot;ImagePuzzle.py&quot;, line 83, in main
    bridges.visualize()
  File &quot;/home/bridges-testing/.local/lib/python3.7/site-packages/bridges-3.1.1-py3.7.egg/bridges/bridges.py&quot;, line 174, in visualize
  File &quot;/home/bridges-testing/.local/lib/python3.7/site-packages/bridges-3.1.1-py3.7.egg/bridges/connector.py&quot;, line 64, in post
  File &quot;/usr/lib/python3/dist-packages/requests/api.py&quot;, line 116, in post
    return request('post', url, data=data, json=json, **kwargs)
  File &quot;/usr/lib/python3/dist-packages/requests/api.py&quot;, line 60, in request
    return session.request(method=method, url=url, **kwargs)
  File &quot;/usr/lib/python3/dist-packages/requests/sessions.py&quot;, line 533, in request
    resp = self.send(prep, **send_kwargs)
  File &quot;/usr/lib/python3/dist-packages/requests/sessions.py&quot;, line 646, in send
    r = adapter.send(request, **kwargs)
  File &quot;/usr/lib/python3/dist-packages/requests/adapters.py&quot;, line 516, in send
    raise ConnectionError(e, request=request)
requests.exceptions.ConnectionError: HTTPConnectionPool(host='bridges-cs.herokuapp.com', port=80): Max retries exceeded with url: /assignments/216.00?apikey=1321549621122&amp;username=bridges_testing (Caused by NewConnectionError('&lt;urllib3.connection.HTTPConnection object at 0x7f642e47fbe0&gt;: Failed to establish a new connection: [Errno -2] Name or service not known'))
could not run python_answer for assignment in ../assignmentdb/16-ImagePuzzle/python_answer
</code></pre>
</div>
    
    </div>
    <div id="pythonlog17" class="logdetails">
      <h2>Assignment 17 full log</h2>
    
<div class="failure">
<h3><span id="pythonlog17-runanswer">Run for Assignment 17</span></h3>
<pre><code>Guessing ControlsTutorial.py is the python file where main is

Traceback (most recent call last):
  File &quot;ControlsTutorial.py&quot;, line 72, in &lt;module&gt;
    main()
  File &quot;ControlsTutorial.py&quot;, line 67, in main
    my_game = ControlsTutorial(217, &quot;BRIDGES_USER_ID&quot;, &quot;BRIDGES_API_KEY&quot;, 30, 30)
  File &quot;ControlsTutorial.py&quot;, line 61, in __init__
    super(ControlsTutorial, self).__init__(assid, login, apikey, cols, rows)
  File &quot;/home/bridges-testing/.local/lib/python3.7/site-packages/bridges-3.1.1-py3.7.egg/bridges/non_blocking_game.py&quot;, line 105, in __init__
  File &quot;/home/bridges-testing/.local/lib/python3.7/site-packages/bridges-3.1.1-py3.7.egg/bridges/gamebase.py&quot;, line 16, in __init__
  File &quot;/home/bridges-testing/.local/lib/python3.7/site-packages/bridges-3.1.1-py3.7.egg/bridges/gamebase.py&quot;, line 33, in game_base_init
  File &quot;/home/bridges-testing/.local/lib/python3.7/site-packages/bridges-3.1.1-py3.7.egg/bridges/socket_connection.py&quot;, line 20, in setup_connection
  File &quot;/home/bridges-testing/.local/lib/python3.7/site-packages/python_socketio-4.6.0-py3.7.egg/socketio/client.py&quot;, line 282, in connect
    six.raise_from(exceptions.ConnectionError(exc.args[0]), None)
  File &quot;&lt;string&gt;&quot;, line 3, in raise_from
socketio.exceptions.ConnectionError: Connection error
could not run python_answer for assignment in ../assignmentdb/17-ControlsTutorial/python_answer
</code></pre>
</div>
    
    </div>
    <div id="pythonlog18" class="logdetails">
      <h2>Assignment 18 full log</h2>
    
<div class="failure">
<h3><span id="pythonlog18-runanswer">Run for Assignment 18</span></h3>
<pre><code>Guessing ControlsTutorialTwo.py is the python file where main is

Traceback (most recent call last):
  File &quot;ControlsTutorialTwo.py&quot;, line 63, in &lt;module&gt;
    main()
  File &quot;ControlsTutorialTwo.py&quot;, line 58, in main
    my_game = StudentClass(218, &quot;STUDENT_USERNAME&quot;, &quot;STUDENT_API_KEY&quot;, 30, 30)
  File &quot;ControlsTutorialTwo.py&quot;, line 52, in __init__
    super(StudentClass, self).__init__(assid, login, apikey, cols, rows)
  File &quot;/home/bridges-testing/.local/lib/python3.7/site-packages/bridges-3.1.1-py3.7.egg/bridges/non_blocking_game.py&quot;, line 105, in __init__
  File &quot;/home/bridges-testing/.local/lib/python3.7/site-packages/bridges-3.1.1-py3.7.egg/bridges/gamebase.py&quot;, line 16, in __init__
  File &quot;/home/bridges-testing/.local/lib/python3.7/site-packages/bridges-3.1.1-py3.7.egg/bridges/gamebase.py&quot;, line 33, in game_base_init
  File &quot;/home/bridges-testing/.local/lib/python3.7/site-packages/bridges-3.1.1-py3.7.egg/bridges/socket_connection.py&quot;, line 20, in setup_connection
  File &quot;/home/bridges-testing/.local/lib/python3.7/site-packages/python_socketio-4.6.0-py3.7.egg/socketio/client.py&quot;, line 282, in connect
    six.raise_from(exceptions.ConnectionError(exc.args[0]), None)
  File &quot;&lt;string&gt;&quot;, line 3, in raise_from
socketio.exceptions.ConnectionError: Connection error
could not run python_answer for assignment in ../assignmentdb/18-ControlsTutorialTwo/python_answer
</code></pre>
</div>
    
    </div>
    <div id="pythonlog19" class="logdetails">
      <h2>Assignment 19 full log</h2>
    
<div class="failure">
<h3><span id="pythonlog19-runanswer">Run for Assignment 19</span></h3>
<pre><code>Guessing BUGSTOMP.py is the python file where main is

Traceback (most recent call last):
  File &quot;BUGSTOMP.py&quot;, line 137, in &lt;module&gt;
    main()
  File &quot;BUGSTOMP.py&quot;, line 132, in main
    my_game = BugStomp(219, &quot;BRIDGES_USERNAME&quot;, &quot;BRIDGES_APIKEY&quot;, 30, 30)
  File &quot;BUGSTOMP.py&quot;, line 125, in __init__
    super(BugStomp, self).__init__(assid, login, apikey, cols, rows)
  File &quot;/home/bridges-testing/.local/lib/python3.7/site-packages/bridges-3.1.1-py3.7.egg/bridges/non_blocking_game.py&quot;, line 105, in __init__
  File &quot;/home/bridges-testing/.local/lib/python3.7/site-packages/bridges-3.1.1-py3.7.egg/bridges/gamebase.py&quot;, line 16, in __init__
  File &quot;/home/bridges-testing/.local/lib/python3.7/site-packages/bridges-3.1.1-py3.7.egg/bridges/gamebase.py&quot;, line 33, in game_base_init
  File &quot;/home/bridges-testing/.local/lib/python3.7/site-packages/bridges-3.1.1-py3.7.egg/bridges/socket_connection.py&quot;, line 20, in setup_connection
  File &quot;/home/bridges-testing/.local/lib/python3.7/site-packages/python_socketio-4.6.0-py3.7.egg/socketio/client.py&quot;, line 282, in connect
    six.raise_from(exceptions.ConnectionError(exc.args[0]), None)
  File &quot;&lt;string&gt;&quot;, line 3, in raise_from
socketio.exceptions.ConnectionError: Connection error
could not run python_answer for assignment in ../assignmentdb/19-Bugstomp/python_answer
</code></pre>
</div>
    
    </div>
    <div id="pythonlog20" class="logdetails">
      <h2>Assignment 20 full log</h2>
    
<div class="failure">
<h3><span id="pythonlog20-runanswer">Run for Assignment 20</span></h3>
<pre><code>Guessing minesweeper.py is the python file where main is

Traceback (most recent call last):
  File &quot;minesweeper.py&quot;, line 174, in &lt;module&gt;
    main()
  File &quot;minesweeper.py&quot;, line 168, in main
    game = Minesweeper(220, &quot;BRIDGES_USER_ID&quot;, &quot;BRIDGES_API_KEY&quot;)
  File &quot;minesweeper.py&quot;, line 33, in __init__
    super(Minesweeper, self).__init__(assid, login, apikey, 10, 10)
  File &quot;/home/bridges-testing/.local/lib/python3.7/site-packages/bridges-3.1.1-py3.7.egg/bridges/non_blocking_game.py&quot;, line 105, in __init__
  File &quot;/home/bridges-testing/.local/lib/python3.7/site-packages/bridges-3.1.1-py3.7.egg/bridges/gamebase.py&quot;, line 16, in __init__
  File &quot;/home/bridges-testing/.local/lib/python3.7/site-packages/bridges-3.1.1-py3.7.egg/bridges/gamebase.py&quot;, line 33, in game_base_init
  File &quot;/home/bridges-testing/.local/lib/python3.7/site-packages/bridges-3.1.1-py3.7.egg/bridges/socket_connection.py&quot;, line 20, in setup_connection
  File &quot;/home/bridges-testing/.local/lib/python3.7/site-packages/python_socketio-4.6.0-py3.7.egg/socketio/client.py&quot;, line 282, in connect
    six.raise_from(exceptions.ConnectionError(exc.args[0]), None)
  File &quot;&lt;string&gt;&quot;, line 3, in raise_from
socketio.exceptions.ConnectionError: Connection error
could not run python_answer for assignment in ../assignmentdb/20-Minesweeper/python_answer
</code></pre>
</div>
    
    </div>
    <div id="pythonlog21" class="logdetails">
      <h2>Assignment 21 full log</h2>
    
<div class="failure">
<h3><span id="pythonlog21-runanswer">Run for Assignment 21</span></h3>
<pre><code>Guessing RaceCar.py is the python file where main is

Traceback (most recent call last):
  File &quot;RaceCar.py&quot;, line 110, in &lt;module&gt;
    main()
  File &quot;RaceCar.py&quot;, line 104, in main
    game = RaceCar(221, &quot;BRIDGES_USER_ID&quot;, &quot;BRIDGES_API_KEY&quot;)
  File &quot;RaceCar.py&quot;, line 23, in __init__
    super(RaceCar, self).__init__(assid, login, apikey, 30, 30)
  File &quot;/home/bridges-testing/.local/lib/python3.7/site-packages/bridges-3.1.1-py3.7.egg/bridges/non_blocking_game.py&quot;, line 105, in __init__
  File &quot;/home/bridges-testing/.local/lib/python3.7/site-packages/bridges-3.1.1-py3.7.egg/bridges/gamebase.py&quot;, line 16, in __init__
  File &quot;/home/bridges-testing/.local/lib/python3.7/site-packages/bridges-3.1.1-py3.7.egg/bridges/gamebase.py&quot;, line 33, in game_base_init
  File &quot;/home/bridges-testing/.local/lib/python3.7/site-packages/bridges-3.1.1-py3.7.egg/bridges/socket_connection.py&quot;, line 20, in setup_connection
  File &quot;/home/bridges-testing/.local/lib/python3.7/site-packages/python_socketio-4.6.0-py3.7.egg/socketio/client.py&quot;, line 282, in connect
    six.raise_from(exceptions.ConnectionError(exc.args[0]), None)
  File &quot;&lt;string&gt;&quot;, line 3, in raise_from
socketio.exceptions.ConnectionError: Connection error
could not run python_answer for assignment in ../assignmentdb/21-RaceCar/python_answer
</code></pre>
</div>
    
    </div>
    <div id="pythonlog22" class="logdetails">
      <h2>Assignment 22 full log</h2>
    
<div class="failure">
<h3><span id="pythonlog22-runanswer">Run for Assignment 22</span></h3>
<pre><code>Guessing Snake.py is the python file where main is

Traceback (most recent call last):
  File &quot;Snake.py&quot;, line 193, in &lt;module&gt;
    main()
  File &quot;Snake.py&quot;, line 188, in main
    my_game = Snake(222, &quot;BRIDGES_USER_ID&quot;, &quot;BRIDGES_API_KEY&quot;, 30, 30)
  File &quot;Snake.py&quot;, line 182, in __init__
    super(Snake, self).__init__(assid, login, apikey, cols, rows)
  File &quot;/home/bridges-testing/.local/lib/python3.7/site-packages/bridges-3.1.1-py3.7.egg/bridges/non_blocking_game.py&quot;, line 105, in __init__
  File &quot;/home/bridges-testing/.local/lib/python3.7/site-packages/bridges-3.1.1-py3.7.egg/bridges/gamebase.py&quot;, line 16, in __init__
  File &quot;/home/bridges-testing/.local/lib/python3.7/site-packages/bridges-3.1.1-py3.7.egg/bridges/gamebase.py&quot;, line 33, in game_base_init
  File &quot;/home/bridges-testing/.local/lib/python3.7/site-packages/bridges-3.1.1-py3.7.egg/bridges/socket_connection.py&quot;, line 20, in setup_connection
  File &quot;/home/bridges-testing/.local/lib/python3.7/site-packages/python_socketio-4.6.0-py3.7.egg/socketio/client.py&quot;, line 282, in connect
    six.raise_from(exceptions.ConnectionError(exc.args[0]), None)
  File &quot;&lt;string&gt;&quot;, line 3, in raise_from
socketio.exceptions.ConnectionError: Connection error
could not run python_answer for assignment in ../assignmentdb/22-Snake/python_answer
</code></pre>
</div>
    
    </div>
    <div id="pythonlog23" class="logdetails">
      <h2>Assignment 23 full log</h2>
    
<div class="failure">
<h3><span id="pythonlog23-runanswer">Run for Assignment 23</span></h3>
<pre><code>Guessing MountainPaths.py is the python file where main is

Traceback (most recent call last):
  File &quot;/usr/lib/python3/dist-packages/urllib3/connection.py&quot;, line 159, in _new_conn
    (self._dns_host, self.port), self.timeout, **extra_kw)
  File &quot;/usr/lib/python3/dist-packages/urllib3/util/connection.py&quot;, line 57, in create_connection
    for res in socket.getaddrinfo(host, port, family, socket.SOCK_STREAM):
  File &quot;/usr/lib/python3.7/socket.py&quot;, line 748, in getaddrinfo
    for res in _socket.getaddrinfo(host, port, family, type, proto, flags):
socket.gaierror: [Errno -2] Name or service not known

During handling of the above exception, another exception occurred:

Traceback (most recent call last):
  File &quot;/usr/lib/python3/dist-packages/urllib3/connectionpool.py&quot;, line 600, in urlopen
    chunked=chunked)
  File &quot;/usr/lib/python3/dist-packages/urllib3/connectionpool.py&quot;, line 354, in _make_request
    conn.request(method, url, **httplib_request_kw)
  File &quot;/usr/lib/python3.7/http/client.py&quot;, line 1244, in request
    self._send_request(method, url, body, headers, encode_chunked)
  File &quot;/usr/lib/python3.7/http/client.py&quot;, line 1290, in _send_request
    self.endheaders(body, encode_chunked=encode_chunked)
  File &quot;/usr/lib/python3.7/http/client.py&quot;, line 1239, in endheaders
    self._send_output(message_body, encode_chunked=encode_chunked)
  File &quot;/usr/lib/python3.7/http/client.py&quot;, line 1026, in _send_output
    self.send(msg)
  File &quot;/usr/lib/python3.7/http/client.py&quot;, line 966, in send
    self.connect()
  File &quot;/usr/lib/python3/dist-packages/urllib3/connection.py&quot;, line 181, in connect
    conn = self._new_conn()
  File &quot;/usr/lib/python3/dist-packages/urllib3/connection.py&quot;, line 168, in _new_conn
    self, &quot;Failed to establish a new connection: %s&quot; % e)
urllib3.exceptions.NewConnectionError: &lt;urllib3.connection.HTTPConnection object at 0x7f3fb01b7da0&gt;: Failed to establish a new connection: [Errno -2] Name or service not known

During handling of the above exception, another exception occurred:

Traceback (most recent call last):
  File &quot;/usr/lib/python3/dist-packages/requests/adapters.py&quot;, line 449, in send
    timeout=timeout
  File &quot;/usr/lib/python3/dist-packages/urllib3/connectionpool.py&quot;, line 638, in urlopen
    _stacktrace=sys.exc_info()[2])
  File &quot;/usr/lib/python3/dist-packages/urllib3/util/retry.py&quot;, line 398, in increment
    raise MaxRetryError(_pool, url, error or ResponseError(cause))
urllib3.exceptions.MaxRetryError: HTTPConnectionPool(host='cci-bridges-elevation-t.dyn.uncc.edu', port=80): Max retries exceeded with url: /hash?minLat=6.02&amp;minLon=44.1&amp;maxLat=9.7&amp;maxLon=47.77&amp;resX=0.02&amp;resY=0.02 (Caused by NewConnectionError('&lt;urllib3.connection.HTTPConnection object at 0x7f3fb01b7da0&gt;: Failed to establish a new connection: [Errno -2] Name or service not known'))

During handling of the above exception, another exception occurred:

Traceback (most recent call last):
  File &quot;MountainPaths.py&quot;, line 129, in &lt;module&gt;
    main()
  File &quot;MountainPaths.py&quot;, line 112, in main
    9.70, 47.77], 0.02)
  File &quot;/home/bridges-testing/.local/lib/python3.7/site-packages/bridges-3.1.1-py3.7.egg/bridges/data_src_dependent/data_source.py&quot;, line 684, in get_elevation_data
  File &quot;/home/bridges-testing/.local/lib/python3.7/site-packages/bridges-3.1.1-py3.7.egg/bridges/data_src_dependent/data_source.py&quot;, line 637, in elevation_server
  File &quot;/usr/lib/python3/dist-packages/requests/api.py&quot;, line 75, in get
    return request('get', url, params=params, **kwargs)
  File &quot;/usr/lib/python3/dist-packages/requests/api.py&quot;, line 60, in request
    return session.request(method=method, url=url, **kwargs)
  File &quot;/usr/lib/python3/dist-packages/requests/sessions.py&quot;, line 533, in request
    resp = self.send(prep, **send_kwargs)
  File &quot;/usr/lib/python3/dist-packages/requests/sessions.py&quot;, line 646, in send
    r = adapter.send(request, **kwargs)
  File &quot;/usr/lib/python3/dist-packages/requests/adapters.py&quot;, line 516, in send
    raise ConnectionError(e, request=request)
requests.exceptions.ConnectionError: HTTPConnectionPool(host='cci-bridges-elevation-t.dyn.uncc.edu', port=80): Max retries exceeded with url: /hash?minLat=6.02&amp;minLon=44.1&amp;maxLat=9.7&amp;maxLon=47.77&amp;resX=0.02&amp;resY=0.02 (Caused by NewConnectionError('&lt;urllib3.connection.HTTPConnection object at 0x7f3fb01b7da0&gt;: Failed to establish a new connection: [Errno -2] Name or service not known'))
could not run python_answer for assignment in ../assignmentdb/23-MountainPaths/python_answer
</code></pre>
</div>
    
    </div>
    <div id="pythonlog24" class="logdetails">
      <h2>Assignment 24 full log</h2>
    
<div class="failure">
<h3><span id="pythonlog24-runanswer">Run for Assignment 24</span></h3>
<pre><code>Guessing ImageCompressionKdTree.py is the python file where main is

RLE ran
Traceback (most recent call last):
  File &quot;/usr/lib/python3/dist-packages/urllib3/connection.py&quot;, line 159, in _new_conn
    (self._dns_host, self.port), self.timeout, **extra_kw)
  File &quot;/usr/lib/python3/dist-packages/urllib3/util/connection.py&quot;, line 57, in create_connection
    for res in socket.getaddrinfo(host, port, family, socket.SOCK_STREAM):
  File &quot;/usr/lib/python3.7/socket.py&quot;, line 748, in getaddrinfo
    for res in _socket.getaddrinfo(host, port, family, type, proto, flags):
socket.gaierror: [Errno -2] Name or service not known

During handling of the above exception, another exception occurred:

Traceback (most recent call last):
  File &quot;/usr/lib/python3/dist-packages/urllib3/connectionpool.py&quot;, line 600, in urlopen
    chunked=chunked)
  File &quot;/usr/lib/python3/dist-packages/urllib3/connectionpool.py&quot;, line 354, in _make_request
    conn.request(method, url, **httplib_request_kw)
  File &quot;/usr/lib/python3.7/http/client.py&quot;, line 1244, in request
    self._send_request(method, url, body, headers, encode_chunked)
  File &quot;/usr/lib/python3.7/http/client.py&quot;, line 1290, in _send_request
    self.endheaders(body, encode_chunked=encode_chunked)
  File &quot;/usr/lib/python3.7/http/client.py&quot;, line 1239, in endheaders
    self._send_output(message_body, encode_chunked=encode_chunked)
  File &quot;/usr/lib/python3.7/http/client.py&quot;, line 1026, in _send_output
    self.send(msg)
  File &quot;/usr/lib/python3.7/http/client.py&quot;, line 966, in send
    self.connect()
  File &quot;/usr/lib/python3/dist-packages/urllib3/connection.py&quot;, line 181, in connect
    conn = self._new_conn()
  File &quot;/usr/lib/python3/dist-packages/urllib3/connection.py&quot;, line 168, in _new_conn
    self, &quot;Failed to establish a new connection: %s&quot; % e)
urllib3.exceptions.NewConnectionError: &lt;urllib3.connection.HTTPConnection object at 0x7f0b2f9185c0&gt;: Failed to establish a new connection: [Errno -2] Name or service not known

During handling of the above exception, another exception occurred:

Traceback (most recent call last):
  File &quot;/usr/lib/python3/dist-packages/requests/adapters.py&quot;, line 449, in send
    timeout=timeout
  File &quot;/usr/lib/python3/dist-packages/urllib3/connectionpool.py&quot;, line 638, in urlopen
    _stacktrace=sys.exc_info()[2])
  File &quot;/usr/lib/python3/dist-packages/urllib3/util/retry.py&quot;, line 398, in increment
    raise MaxRetryError(_pool, url, error or ResponseError(cause))
urllib3.exceptions.MaxRetryError: HTTPConnectionPool(host='bridges-cs.herokuapp.com', port=80): Max retries exceeded with url: /assignments/224.00?apikey=1321549621122&amp;username=bridges_testing (Caused by NewConnectionError('&lt;urllib3.connection.HTTPConnection object at 0x7f0b2f9185c0&gt;: Failed to establish a new connection: [Errno -2] Name or service not known'))

During handling of the above exception, another exception occurred:

Traceback (most recent call last):
  File &quot;ImageCompressionKdTree.py&quot;, line 170, in &lt;module&gt;
    main()
  File &quot;ImageCompressionKdTree.py&quot;, line 57, in main
    bridges.visualize()
  File &quot;/home/bridges-testing/.local/lib/python3.7/site-packages/bridges-3.1.1-py3.7.egg/bridges/bridges.py&quot;, line 174, in visualize
  File &quot;/home/bridges-testing/.local/lib/python3.7/site-packages/bridges-3.1.1-py3.7.egg/bridges/connector.py&quot;, line 64, in post
  File &quot;/usr/lib/python3/dist-packages/requests/api.py&quot;, line 116, in post
    return request('post', url, data=data, json=json, **kwargs)
  File &quot;/usr/lib/python3/dist-packages/requests/api.py&quot;, line 60, in request
    return session.request(method=method, url=url, **kwargs)
  File &quot;/usr/lib/python3/dist-packages/requests/sessions.py&quot;, line 533, in request
    resp = self.send(prep, **send_kwargs)
  File &quot;/usr/lib/python3/dist-packages/requests/sessions.py&quot;, line 646, in send
    r = adapter.send(request, **kwargs)
  File &quot;/usr/lib/python3/dist-packages/requests/adapters.py&quot;, line 516, in send
    raise ConnectionError(e, request=request)
requests.exceptions.ConnectionError: HTTPConnectionPool(host='bridges-cs.herokuapp.com', port=80): Max retries exceeded with url: /assignments/224.00?apikey=1321549621122&amp;username=bridges_testing (Caused by NewConnectionError('&lt;urllib3.connection.HTTPConnection object at 0x7f0b2f9185c0&gt;: Failed to establish a new connection: [Errno -2] Name or service not known'))
could not run python_answer for assignment in ../assignmentdb/24-ImageCompressionKdTree/python_answer
</code></pre>
</div>
    
    </div>
    <div id="pythonlog25" class="logdetails">
      <h2>Assignment 25 full log</h2>
    
<div class="failure">
<h3><span id="pythonlog25-runanswer">Run for Assignment 25</span></h3>
<pre><code>Guessing Patterns.py is the python file where main is

RAW ran
Traceback (most recent call last):
  File &quot;/usr/lib/python3/dist-packages/urllib3/connection.py&quot;, line 159, in _new_conn
    (self._dns_host, self.port), self.timeout, **extra_kw)
  File &quot;/usr/lib/python3/dist-packages/urllib3/util/connection.py&quot;, line 57, in create_connection
    for res in socket.getaddrinfo(host, port, family, socket.SOCK_STREAM):
  File &quot;/usr/lib/python3.7/socket.py&quot;, line 748, in getaddrinfo
    for res in _socket.getaddrinfo(host, port, family, type, proto, flags):
socket.gaierror: [Errno -2] Name or service not known

During handling of the above exception, another exception occurred:

Traceback (most recent call last):
  File &quot;/usr/lib/python3/dist-packages/urllib3/connectionpool.py&quot;, line 600, in urlopen
    chunked=chunked)
  File &quot;/usr/lib/python3/dist-packages/urllib3/connectionpool.py&quot;, line 354, in _make_request
    conn.request(method, url, **httplib_request_kw)
  File &quot;/usr/lib/python3.7/http/client.py&quot;, line 1244, in request
    self._send_request(method, url, body, headers, encode_chunked)
  File &quot;/usr/lib/python3.7/http/client.py&quot;, line 1290, in _send_request
    self.endheaders(body, encode_chunked=encode_chunked)
  File &quot;/usr/lib/python3.7/http/client.py&quot;, line 1239, in endheaders
    self._send_output(message_body, encode_chunked=encode_chunked)
  File &quot;/usr/lib/python3.7/http/client.py&quot;, line 1026, in _send_output
    self.send(msg)
  File &quot;/usr/lib/python3.7/http/client.py&quot;, line 966, in send
    self.connect()
  File &quot;/usr/lib/python3/dist-packages/urllib3/connection.py&quot;, line 181, in connect
    conn = self._new_conn()
  File &quot;/usr/lib/python3/dist-packages/urllib3/connection.py&quot;, line 168, in _new_conn
    self, &quot;Failed to establish a new connection: %s&quot; % e)
urllib3.exceptions.NewConnectionError: &lt;urllib3.connection.HTTPConnection object at 0x7fb8462e4ba8&gt;: Failed to establish a new connection: [Errno -2] Name or service not known

During handling of the above exception, another exception occurred:

Traceback (most recent call last):
  File &quot;/usr/lib/python3/dist-packages/requests/adapters.py&quot;, line 449, in send
    timeout=timeout
  File &quot;/usr/lib/python3/dist-packages/urllib3/connectionpool.py&quot;, line 638, in urlopen
    _stacktrace=sys.exc_info()[2])
  File &quot;/usr/lib/python3/dist-packages/urllib3/util/retry.py&quot;, line 398, in increment
    raise MaxRetryError(_pool, url, error or ResponseError(cause))
urllib3.exceptions.MaxRetryError: HTTPConnectionPool(host='bridges-cs.herokuapp.com', port=80): Max retries exceeded with url: /assignments/225.00?apikey=1321549621122&amp;username=bridges_testing (Caused by NewConnectionError('&lt;urllib3.connection.HTTPConnection object at 0x7fb8462e4ba8&gt;: Failed to establish a new connection: [Errno -2] Name or service not known'))

During handling of the above exception, another exception occurred:

Traceback (most recent call last):
  File &quot;Patterns.py&quot;, line 24, in &lt;module&gt;
    main()
  File &quot;Patterns.py&quot;, line 21, in main
    bridges.visualize()
  File &quot;/home/bridges-testing/.local/lib/python3.7/site-packages/bridges-3.1.1-py3.7.egg/bridges/bridges.py&quot;, line 174, in visualize
  File &quot;/home/bridges-testing/.local/lib/python3.7/site-packages/bridges-3.1.1-py3.7.egg/bridges/connector.py&quot;, line 64, in post
  File &quot;/usr/lib/python3/dist-packages/requests/api.py&quot;, line 116, in post
    return request('post', url, data=data, json=json, **kwargs)
  File &quot;/usr/lib/python3/dist-packages/requests/api.py&quot;, line 60, in request
    return session.request(method=method, url=url, **kwargs)
  File &quot;/usr/lib/python3/dist-packages/requests/sessions.py&quot;, line 533, in request
    resp = self.send(prep, **send_kwargs)
  File &quot;/usr/lib/python3/dist-packages/requests/sessions.py&quot;, line 646, in send
    r = adapter.send(request, **kwargs)
  File &quot;/usr/lib/python3/dist-packages/requests/adapters.py&quot;, line 516, in send
    raise ConnectionError(e, request=request)
requests.exceptions.ConnectionError: HTTPConnectionPool(host='bridges-cs.herokuapp.com', port=80): Max retries exceeded with url: /assignments/225.00?apikey=1321549621122&amp;username=bridges_testing (Caused by NewConnectionError('&lt;urllib3.connection.HTTPConnection object at 0x7fb8462e4ba8&gt;: Failed to establish a new connection: [Errno -2] Name or service not known'))
could not run python_answer for assignment in ../assignmentdb/25-Patterns/python_answer
</code></pre>
</div>
    
    </div>
    <div id="pythonlog26" class="logdetails">
      <h2>Assignment 26 full log</h2>
    
<div class="failure">
<h3><span id="pythonlog26-runanswer">Run for Assignment 26</span></h3>
<pre><code>Guessing TowersOfHanoi.py is the python file where main is

Traceback (most recent call last):
  File &quot;/usr/lib/python3/dist-packages/urllib3/connection.py&quot;, line 159, in _new_conn
    (self._dns_host, self.port), self.timeout, **extra_kw)
  File &quot;/usr/lib/python3/dist-packages/urllib3/util/connection.py&quot;, line 57, in create_connection
    for res in socket.getaddrinfo(host, port, family, socket.SOCK_STREAM):
  File &quot;/usr/lib/python3.7/socket.py&quot;, line 748, in getaddrinfo
    for res in _socket.getaddrinfo(host, port, family, type, proto, flags):
socket.gaierror: [Errno -2] Name or service not known

During handling of the above exception, another exception occurred:

Traceback (most recent call last):
  File &quot;/usr/lib/python3/dist-packages/urllib3/connectionpool.py&quot;, line 600, in urlopen
    chunked=chunked)
  File &quot;/usr/lib/python3/dist-packages/urllib3/connectionpool.py&quot;, line 354, in _make_request
    conn.request(method, url, **httplib_request_kw)
  File &quot;/usr/lib/python3.7/http/client.py&quot;, line 1244, in request
    self._send_request(method, url, body, headers, encode_chunked)
  File &quot;/usr/lib/python3.7/http/client.py&quot;, line 1290, in _send_request
    self.endheaders(body, encode_chunked=encode_chunked)
  File &quot;/usr/lib/python3.7/http/client.py&quot;, line 1239, in endheaders
    self._send_output(message_body, encode_chunked=encode_chunked)
  File &quot;/usr/lib/python3.7/http/client.py&quot;, line 1026, in _send_output
    self.send(msg)
  File &quot;/usr/lib/python3.7/http/client.py&quot;, line 966, in send
    self.connect()
  File &quot;/usr/lib/python3/dist-packages/urllib3/connection.py&quot;, line 181, in connect
    conn = self._new_conn()
  File &quot;/usr/lib/python3/dist-packages/urllib3/connection.py&quot;, line 168, in _new_conn
    self, &quot;Failed to establish a new connection: %s&quot; % e)
urllib3.exceptions.NewConnectionError: &lt;urllib3.connection.HTTPConnection object at 0x7fab99ce66a0&gt;: Failed to establish a new connection: [Errno -2] Name or service not known

During handling of the above exception, another exception occurred:

Traceback (most recent call last):
  File &quot;/usr/lib/python3/dist-packages/requests/adapters.py&quot;, line 449, in send
    timeout=timeout
  File &quot;/usr/lib/python3/dist-packages/urllib3/connectionpool.py&quot;, line 638, in urlopen
    _stacktrace=sys.exc_info()[2])
  File &quot;/usr/lib/python3/dist-packages/urllib3/util/retry.py&quot;, line 398, in increment
    raise MaxRetryError(_pool, url, error or ResponseError(cause))
urllib3.exceptions.MaxRetryError: HTTPConnectionPool(host='bridges-cs.herokuapp.com', port=80): Max retries exceeded with url: /assignments/226.00?apikey=1321549621122&amp;username=bridges_testing (Caused by NewConnectionError('&lt;urllib3.connection.HTTPConnection object at 0x7fab99ce66a0&gt;: Failed to establish a new connection: [Errno -2] Name or service not known'))

During handling of the above exception, another exception occurred:

Traceback (most recent call last):
  File &quot;TowersOfHanoi.py&quot;, line 171, in &lt;module&gt;
    main()
  File &quot;TowersOfHanoi.py&quot;, line 167, in main
    toh_inter(numbDisks, src, aux, dest)
  File &quot;TowersOfHanoi.py&quot;, line 147, in toh_inter
    displayCurrent(src, aux, dest)
  File &quot;TowersOfHanoi.py&quot;, line 105, in displayCurrent
    bridges.visualize()
  File &quot;/home/bridges-testing/.local/lib/python3.7/site-packages/bridges-3.1.1-py3.7.egg/bridges/bridges.py&quot;, line 174, in visualize
  File &quot;/home/bridges-testing/.local/lib/python3.7/site-packages/bridges-3.1.1-py3.7.egg/bridges/connector.py&quot;, line 64, in post
  File &quot;/usr/lib/python3/dist-packages/requests/api.py&quot;, line 116, in post
    return request('post', url, data=data, json=json, **kwargs)
  File &quot;/usr/lib/python3/dist-packages/requests/api.py&quot;, line 60, in request
    return session.request(method=method, url=url, **kwargs)
  File &quot;/usr/lib/python3/dist-packages/requests/sessions.py&quot;, line 533, in request
    resp = self.send(prep, **send_kwargs)
  File &quot;/usr/lib/python3/dist-packages/requests/sessions.py&quot;, line 646, in send
    r = adapter.send(request, **kwargs)
  File &quot;/usr/lib/python3/dist-packages/requests/adapters.py&quot;, line 516, in send
    raise ConnectionError(e, request=request)
requests.exceptions.ConnectionError: HTTPConnectionPool(host='bridges-cs.herokuapp.com', port=80): Max retries exceeded with url: /assignments/226.00?apikey=1321549621122&amp;username=bridges_testing (Caused by NewConnectionError('&lt;urllib3.connection.HTTPConnection object at 0x7fab99ce66a0&gt;: Failed to establish a new connection: [Errno -2] Name or service not known'))
could not run python_answer for assignment in ../assignmentdb/26-TowersOfHanoi/python_answer
</code></pre>
</div>
    
    </div>
    <div id="pythonlog27" class="logdetails">
      <h2>Assignment 27 full log</h2>
    
<div class="failure">
<h3><span id="pythonlog27-runanswer">Run for Assignment 27</span></h3>
<pre><code>Guessing GameGridAdvanced.py is the python file where main is

Traceback (most recent call last):
  File &quot;GameGridAdvanced.py&quot;, line 58, in &lt;module&gt;
    main()
  File &quot;GameGridAdvanced.py&quot;, line 52, in main
    game = Smiley(227, &quot;BRIDGES_USER_ID&quot;, &quot;BRIDGES_API_KEY&quot;)
  File &quot;GameGridAdvanced.py&quot;, line 8, in __init__
    super(Smiley, self).__init__(assid, login, apikey, 10, 10)
  File &quot;/home/bridges-testing/.local/lib/python3.7/site-packages/bridges-3.1.1-py3.7.egg/bridges/non_blocking_game.py&quot;, line 105, in __init__
  File &quot;/home/bridges-testing/.local/lib/python3.7/site-packages/bridges-3.1.1-py3.7.egg/bridges/gamebase.py&quot;, line 16, in __init__
  File &quot;/home/bridges-testing/.local/lib/python3.7/site-packages/bridges-3.1.1-py3.7.egg/bridges/gamebase.py&quot;, line 33, in game_base_init
  File &quot;/home/bridges-testing/.local/lib/python3.7/site-packages/bridges-3.1.1-py3.7.egg/bridges/socket_connection.py&quot;, line 20, in setup_connection
  File &quot;/home/bridges-testing/.local/lib/python3.7/site-packages/python_socketio-4.6.0-py3.7.egg/socketio/client.py&quot;, line 282, in connect
    six.raise_from(exceptions.ConnectionError(exc.args[0]), None)
  File &quot;&lt;string&gt;&quot;, line 3, in raise_from
socketio.exceptions.ConnectionError: Connection error
could not run python_answer for assignment in ../assignmentdb/27-GameGridBasic/python_answer
</code></pre>
</div>
    
    </div>
    <div id="pythonlog28" class="logdetails">
      <h2>Assignment 28 full log</h2>
    
<div class="failure">
<h3><span id="pythonlog28-runanswer">Run for Assignment 28</span></h3>
<pre><code>Guessing BigOhMatters.py is the python file where main is

Traceback (most recent call last):
  File &quot;/usr/lib/python3/dist-packages/urllib3/connection.py&quot;, line 159, in _new_conn
    (self._dns_host, self.port), self.timeout, **extra_kw)
  File &quot;/usr/lib/python3/dist-packages/urllib3/util/connection.py&quot;, line 57, in create_connection
    for res in socket.getaddrinfo(host, port, family, socket.SOCK_STREAM):
  File &quot;/usr/lib/python3.7/socket.py&quot;, line 748, in getaddrinfo
    for res in _socket.getaddrinfo(host, port, family, type, proto, flags):
socket.gaierror: [Errno -2] Name or service not known

During handling of the above exception, another exception occurred:

Traceback (most recent call last):
  File &quot;/usr/lib/python3/dist-packages/urllib3/connectionpool.py&quot;, line 600, in urlopen
    chunked=chunked)
  File &quot;/usr/lib/python3/dist-packages/urllib3/connectionpool.py&quot;, line 354, in _make_request
    conn.request(method, url, **httplib_request_kw)
  File &quot;/usr/lib/python3.7/http/client.py&quot;, line 1244, in request
    self._send_request(method, url, body, headers, encode_chunked)
  File &quot;/usr/lib/python3.7/http/client.py&quot;, line 1290, in _send_request
    self.endheaders(body, encode_chunked=encode_chunked)
  File &quot;/usr/lib/python3.7/http/client.py&quot;, line 1239, in endheaders
    self._send_output(message_body, encode_chunked=encode_chunked)
  File &quot;/usr/lib/python3.7/http/client.py&quot;, line 1026, in _send_output
    self.send(msg)
  File &quot;/usr/lib/python3.7/http/client.py&quot;, line 966, in send
    self.connect()
  File &quot;/usr/lib/python3/dist-packages/urllib3/connection.py&quot;, line 181, in connect
    conn = self._new_conn()
  File &quot;/usr/lib/python3/dist-packages/urllib3/connection.py&quot;, line 168, in _new_conn
    self, &quot;Failed to establish a new connection: %s&quot; % e)
urllib3.exceptions.NewConnectionError: &lt;urllib3.connection.HTTPConnection object at 0x7f3a1e7d0b38&gt;: Failed to establish a new connection: [Errno -2] Name or service not known

During handling of the above exception, another exception occurred:

Traceback (most recent call last):
  File &quot;/usr/lib/python3/dist-packages/requests/adapters.py&quot;, line 449, in send
    timeout=timeout
  File &quot;/usr/lib/python3/dist-packages/urllib3/connectionpool.py&quot;, line 638, in urlopen
    _stacktrace=sys.exc_info()[2])
  File &quot;/usr/lib/python3/dist-packages/urllib3/util/retry.py&quot;, line 398, in increment
    raise MaxRetryError(_pool, url, error or ResponseError(cause))
urllib3.exceptions.MaxRetryError: HTTPConnectionPool(host='bridges-cs.herokuapp.com', port=80): Max retries exceeded with url: /assignments/228.00?apikey=1321549621122&amp;username=bridges_testing (Caused by NewConnectionError('&lt;urllib3.connection.HTTPConnection object at 0x7f3a1e7d0b38&gt;: Failed to establish a new connection: [Errno -2] Name or service not known'))

During handling of the above exception, another exception occurred:

Traceback (most recent call last):
  File &quot;BigOhMatters.py&quot;, line 148, in &lt;module&gt;
    main()
  File &quot;BigOhMatters.py&quot;, line 143, in main
    task1(bridges)
  File &quot;BigOhMatters.py&quot;, line 41, in task1
    bridges.visualize()
  File &quot;/home/bridges-testing/.local/lib/python3.7/site-packages/bridges-3.1.1-py3.7.egg/bridges/bridges.py&quot;, line 174, in visualize
  File &quot;/home/bridges-testing/.local/lib/python3.7/site-packages/bridges-3.1.1-py3.7.egg/bridges/connector.py&quot;, line 64, in post
  File &quot;/usr/lib/python3/dist-packages/requests/api.py&quot;, line 116, in post
    return request('post', url, data=data, json=json, **kwargs)
  File &quot;/usr/lib/python3/dist-packages/requests/api.py&quot;, line 60, in request
    return session.request(method=method, url=url, **kwargs)
  File &quot;/usr/lib/python3/dist-packages/requests/sessions.py&quot;, line 533, in request
    resp = self.send(prep, **send_kwargs)
  File &quot;/usr/lib/python3/dist-packages/requests/sessions.py&quot;, line 646, in send
    r = adapter.send(request, **kwargs)
  File &quot;/usr/lib/python3/dist-packages/requests/adapters.py&quot;, line 516, in send
    raise ConnectionError(e, request=request)
requests.exceptions.ConnectionError: HTTPConnectionPool(host='bridges-cs.herokuapp.com', port=80): Max retries exceeded with url: /assignments/228.00?apikey=1321549621122&amp;username=bridges_testing (Caused by NewConnectionError('&lt;urllib3.connection.HTTPConnection object at 0x7f3a1e7d0b38&gt;: Failed to establish a new connection: [Errno -2] Name or service not known'))
could not run python_answer for assignment in ../assignmentdb/28-BigOhMatters/python_answer
</code></pre>
</div>
    
    </div>
    <div id="pythonlog29" class="logdetails">
      <h2>Assignment 29 full log</h2>
    
<div class="failure">
<h3><span id="pythonlog29-runanswer">Run for Assignment 29</span></h3>
<pre><code>Guessing SortingBenchmark.py is the python file where main is

Traceback (most recent call last):
  File &quot;/usr/lib/python3/dist-packages/urllib3/connection.py&quot;, line 159, in _new_conn
    (self._dns_host, self.port), self.timeout, **extra_kw)
  File &quot;/usr/lib/python3/dist-packages/urllib3/util/connection.py&quot;, line 57, in create_connection
    for res in socket.getaddrinfo(host, port, family, socket.SOCK_STREAM):
  File &quot;/usr/lib/python3.7/socket.py&quot;, line 748, in getaddrinfo
    for res in _socket.getaddrinfo(host, port, family, type, proto, flags):
socket.gaierror: [Errno -2] Name or service not known

During handling of the above exception, another exception occurred:

Traceback (most recent call last):
  File &quot;/usr/lib/python3/dist-packages/urllib3/connectionpool.py&quot;, line 600, in urlopen
    chunked=chunked)
  File &quot;/usr/lib/python3/dist-packages/urllib3/connectionpool.py&quot;, line 354, in _make_request
    conn.request(method, url, **httplib_request_kw)
  File &quot;/usr/lib/python3.7/http/client.py&quot;, line 1244, in request
    self._send_request(method, url, body, headers, encode_chunked)
  File &quot;/usr/lib/python3.7/http/client.py&quot;, line 1290, in _send_request
    self.endheaders(body, encode_chunked=encode_chunked)
  File &quot;/usr/lib/python3.7/http/client.py&quot;, line 1239, in endheaders
    self._send_output(message_body, encode_chunked=encode_chunked)
  File &quot;/usr/lib/python3.7/http/client.py&quot;, line 1026, in _send_output
    self.send(msg)
  File &quot;/usr/lib/python3.7/http/client.py&quot;, line 966, in send
    self.connect()
  File &quot;/usr/lib/python3/dist-packages/urllib3/connection.py&quot;, line 181, in connect
    conn = self._new_conn()
  File &quot;/usr/lib/python3/dist-packages/urllib3/connection.py&quot;, line 168, in _new_conn
    self, &quot;Failed to establish a new connection: %s&quot; % e)
urllib3.exceptions.NewConnectionError: &lt;urllib3.connection.HTTPConnection object at 0x7f7377cc54e0&gt;: Failed to establish a new connection: [Errno -2] Name or service not known

During handling of the above exception, another exception occurred:

Traceback (most recent call last):
  File &quot;/usr/lib/python3/dist-packages/requests/adapters.py&quot;, line 449, in send
    timeout=timeout
  File &quot;/usr/lib/python3/dist-packages/urllib3/connectionpool.py&quot;, line 638, in urlopen
    _stacktrace=sys.exc_info()[2])
  File &quot;/usr/lib/python3/dist-packages/urllib3/util/retry.py&quot;, line 398, in increment
    raise MaxRetryError(_pool, url, error or ResponseError(cause))
urllib3.exceptions.MaxRetryError: HTTPConnectionPool(host='bridges-cs.herokuapp.com', port=80): Max retries exceeded with url: /assignments/229.00?apikey=1321549621122&amp;username=bridges_testing (Caused by NewConnectionError('&lt;urllib3.connection.HTTPConnection object at 0x7f7377cc54e0&gt;: Failed to establish a new connection: [Errno -2] Name or service not known'))

During handling of the above exception, another exception occurred:

Traceback (most recent call last):
  File &quot;SortingBenchmark.py&quot;, line 63, in &lt;module&gt;
    main()
  File &quot;SortingBenchmark.py&quot;, line 46, in main
    bridges.visualize()
  File &quot;/home/bridges-testing/.local/lib/python3.7/site-packages/bridges-3.1.1-py3.7.egg/bridges/bridges.py&quot;, line 174, in visualize
  File &quot;/home/bridges-testing/.local/lib/python3.7/site-packages/bridges-3.1.1-py3.7.egg/bridges/connector.py&quot;, line 64, in post
  File &quot;/usr/lib/python3/dist-packages/requests/api.py&quot;, line 116, in post
    return request('post', url, data=data, json=json, **kwargs)
  File &quot;/usr/lib/python3/dist-packages/requests/api.py&quot;, line 60, in request
    return session.request(method=method, url=url, **kwargs)
  File &quot;/usr/lib/python3/dist-packages/requests/sessions.py&quot;, line 533, in request
    resp = self.send(prep, **send_kwargs)
  File &quot;/usr/lib/python3/dist-packages/requests/sessions.py&quot;, line 646, in send
    r = adapter.send(request, **kwargs)
  File &quot;/usr/lib/python3/dist-packages/requests/adapters.py&quot;, line 516, in send
    raise ConnectionError(e, request=request)
requests.exceptions.ConnectionError: HTTPConnectionPool(host='bridges-cs.herokuapp.com', port=80): Max retries exceeded with url: /assignments/229.00?apikey=1321549621122&amp;username=bridges_testing (Caused by NewConnectionError('&lt;urllib3.connection.HTTPConnection object at 0x7f7377cc54e0&gt;: Failed to establish a new connection: [Errno -2] Name or service not known'))
could not run python_answer for assignment in ../assignmentdb/29-SortingBenchmark/python_answer
</code></pre>
</div>
    
    </div>
    <div id="pythonlog30" class="logdetails">
      <h2>Assignment 30 full log</h2>
    
<div class="failure">
<h3><span id="pythonlog30-runanswer">Run for Assignment 30</span></h3>
<pre><code>Guessing TemporalBaconNumber.py is the python file where main is

Traceback (most recent call last):
  File &quot;/usr/lib/python3.7/urllib/request.py&quot;, line 1324, in do_open
    encode_chunked=req.has_header('Transfer-encoding'))
  File &quot;/usr/lib/python3.7/http/client.py&quot;, line 1244, in request
    self._send_request(method, url, body, headers, encode_chunked)
  File &quot;/usr/lib/python3.7/http/client.py&quot;, line 1290, in _send_request
    self.endheaders(body, encode_chunked=encode_chunked)
  File &quot;/usr/lib/python3.7/http/client.py&quot;, line 1239, in endheaders
    self._send_output(message_body, encode_chunked=encode_chunked)
  File &quot;/usr/lib/python3.7/http/client.py&quot;, line 1026, in _send_output
    self.send(msg)
  File &quot;/usr/lib/python3.7/http/client.py&quot;, line 966, in send
    self.connect()
  File &quot;/usr/lib/python3.7/http/client.py&quot;, line 1399, in connect
    super().connect()
  File &quot;/usr/lib/python3.7/http/client.py&quot;, line 938, in connect
    (self.host,self.port), self.timeout, self.source_address)
  File &quot;/usr/lib/python3.7/socket.py&quot;, line 707, in create_connection
    for res in getaddrinfo(host, port, 0, SOCK_STREAM):
  File &quot;/usr/lib/python3.7/socket.py&quot;, line 748, in getaddrinfo
    for res in _socket.getaddrinfo(host, port, family, type, proto, flags):
socket.gaierror: [Errno -2] Name or service not known

During handling of the above exception, another exception occurred:

Traceback (most recent call last):
  File &quot;TemporalBaconNumber.py&quot;, line 129, in &lt;module&gt;
    main()
  File &quot;TemporalBaconNumber.py&quot;, line 51, in main
    v = get_wiki_data_actor_movie(year, 1981)
  File &quot;/home/bridges-testing/.local/lib/python3.7/site-packages/bridges-3.1.1-py3.7.egg/bridges/data_src_dependent/data_source.py&quot;, line 756, in get_wiki_data_actor_movie
  File &quot;/home/bridges-testing/.local/lib/python3.7/site-packages/bridges-3.1.1-py3.7.egg/bridges/data_src_dependent/data_source.py&quot;, line 738, in _get_wiki_actor_movie_direct
  File &quot;/home/bridges-testing/.local/lib/python3.7/site-packages/SPARQLWrapper-1.8.5-py3.7.egg/SPARQLWrapper/Wrapper.py&quot;, line 1107, in query
    return QueryResult(self._query())
  File &quot;/home/bridges-testing/.local/lib/python3.7/site-packages/SPARQLWrapper-1.8.5-py3.7.egg/SPARQLWrapper/Wrapper.py&quot;, line 1073, in _query
    response = urlopener(request)
  File &quot;/usr/lib/python3.7/urllib/request.py&quot;, line 222, in urlopen
    return opener.open(url, data, timeout)
  File &quot;/usr/lib/python3.7/urllib/request.py&quot;, line 525, in open
    response = self._open(req, data)
  File &quot;/usr/lib/python3.7/urllib/request.py&quot;, line 543, in _open
    '_open', req)
  File &quot;/usr/lib/python3.7/urllib/request.py&quot;, line 503, in _call_chain
    result = func(*args)
  File &quot;/usr/lib/python3.7/urllib/request.py&quot;, line 1367, in https_open
    context=self._context, check_hostname=self._check_hostname)
  File &quot;/usr/lib/python3.7/urllib/request.py&quot;, line 1326, in do_open
    raise URLError(err)
urllib.error.URLError: &lt;urlopen error [Errno -2] Name or service not known&gt;
could not run python_answer for assignment in ../assignmentdb/30-TemporalBaconNumber/python_answer
</code></pre>
</div>
    
    </div>
    <div id="pythonlog31" class="logdetails">
      <h2>Assignment 31 full log</h2>
    
<div class="failure">
<h3><span id="pythonlog31-runanswer">Run for Assignment 31</span></h3>
<pre><code>Guessing TemporalPageRank.py is the python file where main is

Traceback (most recent call last):
  File &quot;/usr/lib/python3.7/urllib/request.py&quot;, line 1324, in do_open
    encode_chunked=req.has_header('Transfer-encoding'))
  File &quot;/usr/lib/python3.7/http/client.py&quot;, line 1244, in request
    self._send_request(method, url, body, headers, encode_chunked)
  File &quot;/usr/lib/python3.7/http/client.py&quot;, line 1290, in _send_request
    self.endheaders(body, encode_chunked=encode_chunked)
  File &quot;/usr/lib/python3.7/http/client.py&quot;, line 1239, in endheaders
    self._send_output(message_body, encode_chunked=encode_chunked)
  File &quot;/usr/lib/python3.7/http/client.py&quot;, line 1026, in _send_output
    self.send(msg)
  File &quot;/usr/lib/python3.7/http/client.py&quot;, line 966, in send
    self.connect()
  File &quot;/usr/lib/python3.7/http/client.py&quot;, line 1399, in connect
    super().connect()
  File &quot;/usr/lib/python3.7/http/client.py&quot;, line 938, in connect
    (self.host,self.port), self.timeout, self.source_address)
  File &quot;/usr/lib/python3.7/socket.py&quot;, line 707, in create_connection
    for res in getaddrinfo(host, port, 0, SOCK_STREAM):
  File &quot;/usr/lib/python3.7/socket.py&quot;, line 748, in getaddrinfo
    for res in _socket.getaddrinfo(host, port, family, type, proto, flags):
socket.gaierror: [Errno -2] Name or service not known

During handling of the above exception, another exception occurred:

Traceback (most recent call last):
  File &quot;TemporalPageRank.py&quot;, line 104, in &lt;module&gt;
    main()
  File &quot;TemporalPageRank.py&quot;, line 42, in main
    v = get_wiki_data_actor_movie(year, 1975)
  File &quot;/home/bridges-testing/.local/lib/python3.7/site-packages/bridges-3.1.1-py3.7.egg/bridges/data_src_dependent/data_source.py&quot;, line 756, in get_wiki_data_actor_movie
  File &quot;/home/bridges-testing/.local/lib/python3.7/site-packages/bridges-3.1.1-py3.7.egg/bridges/data_src_dependent/data_source.py&quot;, line 738, in _get_wiki_actor_movie_direct
  File &quot;/home/bridges-testing/.local/lib/python3.7/site-packages/SPARQLWrapper-1.8.5-py3.7.egg/SPARQLWrapper/Wrapper.py&quot;, line 1107, in query
    return QueryResult(self._query())
  File &quot;/home/bridges-testing/.local/lib/python3.7/site-packages/SPARQLWrapper-1.8.5-py3.7.egg/SPARQLWrapper/Wrapper.py&quot;, line 1073, in _query
    response = urlopener(request)
  File &quot;/usr/lib/python3.7/urllib/request.py&quot;, line 222, in urlopen
    return opener.open(url, data, timeout)
  File &quot;/usr/lib/python3.7/urllib/request.py&quot;, line 525, in open
    response = self._open(req, data)
  File &quot;/usr/lib/python3.7/urllib/request.py&quot;, line 543, in _open
    '_open', req)
  File &quot;/usr/lib/python3.7/urllib/request.py&quot;, line 503, in _call_chain
    result = func(*args)
  File &quot;/usr/lib/python3.7/urllib/request.py&quot;, line 1367, in https_open
    context=self._context, check_hostname=self._check_hostname)
  File &quot;/usr/lib/python3.7/urllib/request.py&quot;, line 1326, in do_open
    raise URLError(err)
urllib.error.URLError: &lt;urlopen error [Errno -2] Name or service not known&gt;
could not run python_answer for assignment in ../assignmentdb/31-TemporalPageRank/python_answer
</code></pre>
</div>
    
    </div>
    <div id="pythonlog32" class="logdetails">
      <h2>Assignment 32 full log</h2>
    
<div class="failure">
<h3><span id="pythonlog32-runanswer">Run for Assignment 32</span></h3>
<pre><code>Guessing TicTacToe.py is the python file where main is

Traceback (most recent call last):
  File &quot;TicTacToe.py&quot;, line 93, in &lt;module&gt;
    main()
  File &quot;TicTacToe.py&quot;, line 86, in main
    game = TicTacToe(232, &quot;BRIDGES_USER_ID&quot;, &quot;BRIDGES_API_KEY&quot;)
  File &quot;TicTacToe.py&quot;, line 5, in __init__
    super(TicTacToe, self).__init__(assid, login, apikey, 3, 3)
  File &quot;/home/bridges-testing/.local/lib/python3.7/site-packages/bridges-3.1.1-py3.7.egg/bridges/non_blocking_game.py&quot;, line 105, in __init__
  File &quot;/home/bridges-testing/.local/lib/python3.7/site-packages/bridges-3.1.1-py3.7.egg/bridges/gamebase.py&quot;, line 16, in __init__
  File &quot;/home/bridges-testing/.local/lib/python3.7/site-packages/bridges-3.1.1-py3.7.egg/bridges/gamebase.py&quot;, line 33, in game_base_init
  File &quot;/home/bridges-testing/.local/lib/python3.7/site-packages/bridges-3.1.1-py3.7.egg/bridges/socket_connection.py&quot;, line 20, in setup_connection
  File &quot;/home/bridges-testing/.local/lib/python3.7/site-packages/python_socketio-4.6.0-py3.7.egg/socketio/client.py&quot;, line 282, in connect
    six.raise_from(exceptions.ConnectionError(exc.args[0]), None)
  File &quot;&lt;string&gt;&quot;, line 3, in raise_from
socketio.exceptions.ConnectionError: Connection error
could not run python_answer for assignment in ../assignmentdb/32-TicTacToe/python_answer
</code></pre>
</div>
    
    </div>
    <div id="pythonlog33" class="logdetails">
      <h2>Assignment 33 full log</h2>
    
<div class="failure">
<h3><span id="pythonlog33-runanswer">Run for Assignment 33</span></h3>
<pre><code>can't guess a python file
could not run python_answer for assignment in ../assignmentdb/33-AudioMixing/python_answer
</code></pre>
</div>
    
    </div>
    <div id="pythonlog34" class="logdetails">
      <h2>Assignment 34 full log</h2>
    
<div class="failure">
<h3><span id="pythonlog34-runanswer">Run for Assignment 34</span></h3>
<pre><code>Guessing GameTutorial.py is the python file where main is

Traceback (most recent call last):
  File &quot;GameTutorial.py&quot;, line 71, in &lt;module&gt;
    main()
  File &quot;GameTutorial.py&quot;, line 66, in main
    game = GameTutorial(234, &quot;BRIDGES_USER_ID&quot;, &quot;BRIDGES_API_KEY&quot;)
  File &quot;GameTutorial.py&quot;, line 7, in __init__
    super().__init__(assid, user_id,  api_key, 10, 10)
  File &quot;/home/bridges-testing/.local/lib/python3.7/site-packages/bridges-3.1.1-py3.7.egg/bridges/non_blocking_game.py&quot;, line 105, in __init__
  File &quot;/home/bridges-testing/.local/lib/python3.7/site-packages/bridges-3.1.1-py3.7.egg/bridges/gamebase.py&quot;, line 16, in __init__
  File &quot;/home/bridges-testing/.local/lib/python3.7/site-packages/bridges-3.1.1-py3.7.egg/bridges/gamebase.py&quot;, line 33, in game_base_init
  File &quot;/home/bridges-testing/.local/lib/python3.7/site-packages/bridges-3.1.1-py3.7.egg/bridges/socket_connection.py&quot;, line 20, in setup_connection
  File &quot;/home/bridges-testing/.local/lib/python3.7/site-packages/python_socketio-4.6.0-py3.7.egg/socketio/client.py&quot;, line 282, in connect
    six.raise_from(exceptions.ConnectionError(exc.args[0]), None)
  File &quot;&lt;string&gt;&quot;, line 3, in raise_from
socketio.exceptions.ConnectionError: Connection error
could not run python_answer for assignment in ../assignmentdb/34-GameTutorials/python_answer
</code></pre>
</div>
    
    </div>
    <div id="pythonlog35" class="logdetails">
      <h2>Assignment 35 full log</h2>
    
<div class="failure">
<h3><span id="pythonlog35-runanswer">Run for Assignment 35</span></h3>
<pre><code>assignment 35 has no python_answer directory
</code></pre>
</div>
    
    </div>
    <div id="pythonlog36" class="logdetails">
      <h2>Assignment 36 full log</h2>
    
<div class="failure">
<h3><span id="pythonlog36-runanswer">Run for Assignment 36</span></h3>
<pre><code>assignment 36 has no python_answer directory
</code></pre>
</div>
    
    </div>
    <div id="pythonlog37" class="logdetails">
      <h2>Assignment 37 full log</h2>
    
<div class="failure">
<h3><span id="pythonlog37-runanswer">Run for Assignment 37</span></h3>
<pre><code>can't guess a python file
could not run python_answer for assignment in ../assignmentdb/37-BST_Earthquakes/python_answer
</code></pre>
</div>
    
    </div>
    <div id="pythonlog38" class="logdetails">
      <h2>Assignment 38 full log</h2>
    
<div class="failure">
<h3><span id="pythonlog38-runanswer">Run for Assignment 38</span></h3>
<pre><code>assignment 38 has no python_answer directory
</code></pre>
</div>
    
    </div>
    <div id="pythonlog39" class="logdetails">
      <h2>Assignment 39 full log</h2>
    
<div class="failure">
<h3><span id="pythonlog39-runanswer">Run for Assignment 39</span></h3>
<pre><code>assignment 39 has no python_answer directory
</code></pre>
</div>
    
    </div>
    <div id="pythonlog40" class="logdetails">
      <h2>Assignment 40 full log</h2>
    
<div class="failure">
<h3><span id="pythonlog40-runanswer">Run for Assignment 40</span></h3>
<pre><code>assignment 40 has no python_answer directory
</code></pre>
</div>
    
    </div>
    <div id="pythonlog41" class="logdetails">
      <h2>Assignment 41 full log</h2>
    
<div class="failure">
<h3><span id="pythonlog41-runanswer">Run for Assignment 41</span></h3>
<pre><code>Guessing SpaceInvaders.py is the python file where main is

Traceback (most recent call last):
  File &quot;SpaceInvaders.py&quot;, line 234, in &lt;module&gt;
    main()
  File &quot;SpaceInvaders.py&quot;, line 227, in main
    si = SpaceInvaders(41, &quot;BRIDGES_USER_ID&quot;, &quot;BRIDGES_API_KEY&quot;, 20, 15)
  File &quot;SpaceInvaders.py&quot;, line 40, in __init__
    super(SpaceInvaders, self).__init__(assid, login, apikey, cols, rows)
  File &quot;/home/bridges-testing/.local/lib/python3.7/site-packages/bridges-3.1.1-py3.7.egg/bridges/non_blocking_game.py&quot;, line 105, in __init__
  File &quot;/home/bridges-testing/.local/lib/python3.7/site-packages/bridges-3.1.1-py3.7.egg/bridges/gamebase.py&quot;, line 16, in __init__
  File &quot;/home/bridges-testing/.local/lib/python3.7/site-packages/bridges-3.1.1-py3.7.egg/bridges/gamebase.py&quot;, line 33, in game_base_init
  File &quot;/home/bridges-testing/.local/lib/python3.7/site-packages/bridges-3.1.1-py3.7.egg/bridges/socket_connection.py&quot;, line 20, in setup_connection
  File &quot;/home/bridges-testing/.local/lib/python3.7/site-packages/python_socketio-4.6.0-py3.7.egg/socketio/client.py&quot;, line 282, in connect
    six.raise_from(exceptions.ConnectionError(exc.args[0]), None)
  File &quot;&lt;string&gt;&quot;, line 3, in raise_from
socketio.exceptions.ConnectionError: Connection error
could not run python_answer for assignment in ../assignmentdb/41-SpaceInvaders/python_answer
</code></pre>
</div>
    
    </div>
    <div id="pythonlog42" class="logdetails">
      <h2>Assignment 42 full log</h2>
    
<div class="failure">
<h3><span id="pythonlog42-runanswer">Run for Assignment 42</span></h3>
<pre><code>can't guess a python file
could not run python_answer for assignment in ../assignmentdb/42-Covid/python_answer
</code></pre>
</div>
    
    </div>
    <div id="pythonlog43" class="logdetails">
      <h2>Assignment 43 full log</h2>
    
<div class="success">
<h3><span id="pythonlog43-runanswer">Run for Assignment 43</span></h3>
<pre><code>Guessing spatialindexing.py is the python file where main is


Check Your Visualization at the following link:

http://bridges-cs.herokuapp.com/assignments/243/bridges_testing


0
10
20
30
40
50
60
70
80
90
100
110
120
130
140
150
160
170
180
190
200
210
220
230
240
250
260
270
280
290
300
310
320
330
340
350
360
370
380
390
400
410
420
430
440
450
460
470
480
490
500
510
520
530
540
550
560
570
580
590
600
610
620
630
640
650
660
670
680
690
700
710
720
730
740
750
760
770
780
790
800
810
820
830
840
850
860
870
880
890
900
910
920
930
940
950
960
970
980
990
14.471686124801636
</code></pre>
</div>
    
    </div>
    <div id="pythonlog44" class="logdetails">
      <h2>Assignment 44 full log</h2>
    
<div class="failure">
<h3><span id="pythonlog44-runanswer">Run for Assignment 44</span></h3>
<pre><code>assignment 44 has no python_answer directory
</code></pre>
</div>
    
    </div>
    <div id="pythonlog45" class="logdetails">
      <h2>Assignment 45 full log</h2>
    
<div class="success">
<h3><span id="pythonlog45-runanswer">Run for Assignment 45</span></h3>
<pre><code>Guessing ExplorerRobot.py is the python file where main is

passing student credentials to server..
Subscribing to keypress events.. &lt;bridges.input_helper.InputHelper object at 0x7fd71853fd30&gt;
limiting number of frame to 10

Check Your Visualization at the following link:

http://bridges-games.herokuapp.com/assignments/45/bridges_testing


frame limit of 10 frames reached
</code></pre>
</div>
    
    </div>
    <div id="pythonlog46" class="logdetails">
      <h2>Assignment 46 full log</h2>
    
<div class="failure">
<h3><span id="pythonlog46-runanswer">Run for Assignment 46</span></h3>
<pre><code>assignment 46 has no python_answer directory
</code></pre>
</div>
    
    </div>
    <div id="pythonlog47" class="logdetails">
      <h2>Assignment 47 full log</h2>
    
<div class="failure">
<h3><span id="pythonlog47-runanswer">Run for Assignment 47</span></h3>
<pre><code>assignment 47 has no python_answer directory
</code></pre>
</div>
    
    </div>
    <div id="pythonlog48" class="logdetails">
      <h2>Assignment 48 full log</h2>
    
<div class="failure">
<h3><span id="pythonlog48-runanswer">Run for Assignment 48</span></h3>
<pre><code>assignment 48 has no python_answer directory
</code></pre>
</div>
    
    </div>
    <div id="pythonlog49" class="logdetails">
      <h2>Assignment 49 full log</h2>
    
<div class="failure">
<h3><span id="pythonlog49-runanswer">Run for Assignment 49</span></h3>
<pre><code>assignment 49 has no python_answer directory
</code></pre>
</div>
    
    </div>
    <div id="pythonlog50" class="logdetails">
      <h2>Assignment 50 full log</h2>
    
<div class="failure">
<h3><span id="pythonlog50-runanswer">Run for Assignment 50</span></h3>
<pre><code>assignment 50 has no python_answer directory
</code></pre>
</div>
    
    </div>
    <div id="pythonlog51" class="logdetails">
      <h2>Assignment 51 full log</h2>
    
<div class="failure">
<h3><span id="pythonlog51-runanswer">Run for Assignment 51</span></h3>
<pre><code>assignment 51 has no python_answer directory
</code></pre>
</div>
    
    </div>
    <div id="pythonlog52" class="logdetails">
      <h2>Assignment 52 full log</h2>
    
<div class="failure">
<h3><span id="pythonlog52-runanswer">Run for Assignment 52</span></h3>
<pre><code>can't guess a python file
could not run python_answer for assignment in ../assignmentdb/52-AudioWave/python_answer
</code></pre>
</div>
    
    </div>
    <div id="pythonlog53" class="logdetails">
      <h2>Assignment 53 full log</h2>
    
<div class="failure">
<h3><span id="pythonlog53-runanswer">Run for Assignment 53</span></h3>
<pre><code>assignment 53 has no python_answer directory
</code></pre>
</div>
    
    </div>
    <div id="pythonlog54" class="logdetails">
      <h2>Assignment 54 full log</h2>
    
<div class="failure">
<h3><span id="pythonlog54-runanswer">Run for Assignment 54</span></h3>
<pre><code>assignment 54 has no python_answer directory
</code></pre>
</div>
    
    </div>
    <div id="pythonlog55" class="logdetails">
      <h2>Assignment 55 full log</h2>
    
<div class="failure">
<h3><span id="pythonlog55-runanswer">Run for Assignment 55</span></h3>
<pre><code>can't guess a python file
could not run python_answer for assignment in ../assignmentdb/55-FreqencyPlayer/python_answer
</code></pre>
</div>
    
    </div>
  </body>
